Workbook

Sheet TMP(NewPCC)_IndirectCost
C1: =Pay_Items!D55 -> Joint Clean and Reseal, Concrete | I1: Hidden
A2: Initial Construction Costs: | E2: Average Daily Revenue: | F2: =IF('General Information'!$D$38="Yes",SUMIF(RevenueData!$A:$A,'General Information'!$D$10,RevenueData!$B:$B)+SUMIF(RevenueData!$A:$A,'General Information'!$D$10,RevenueData!$C:$C)+SUMIF(RevenueData!$A:$A,'General Information'!$D$10,RevenueData!$D:$D)+SUMIF(RevenueData!$A:$A,'General Information'!$D$10,RevenueData!$E:$E)+SUMIF(RevenueData!$A:$A,'General Information'!$D$10,RevenueData!$F:$F)+SUMIF(RevenueData!$A:$A,'General Information'!$D$10,RevenueData!$G:$G)+SUMIF(RevenueData!$A:$A,'General Information'!$D$10,RevenueData!$H:$H),0) -> 3239.39 | G2: =IF(AND('General Information'!$D$38="Yes",F2=0),"No revenue data for this airport - lost revenue set to $0. Contact Aeronautics.","") | J2: Maintenance 1 | R2: Rehabilitation 1
A4: Pavement Type: | C4: New PCC | E4: Maintenance 1 Duration (Days) | F4: =ROUNDUP(C5*550/(50*100/9)/10000,0)+ROUNDUP(C5*'Maintenance Policies'!D38/10000,0)+ROUNDUP(C5*'Maintenance Policies'!D39/5000,0)+ROUNDUP(C5*'Maintenance Policies'!D40/5000,0) -> 10
A5: Mainline Pavement Area: | C5: ='General Information'!D26 -> 66667 | D5: S.Y. | E5: Rehabilitation 1 Duration (Days) | F5: =ROUNDUP(C5*550/(50*100/9)/10000,0)+ROUNDUP(C5*'Maintenance Policies'!D44/10000,0)+ROUNDUP(C5*'Maintenance Policies'!D43/5000,0)+ROUNDUP(C5*'Maintenance Policies'!D42/5000,0)+ROUNDUP(C5*'Maintenance Policies'!D41/1000,0)+7 -> 19
A6: Initial Construction Year: | C6: ='General Information'!D25 -> 2028
A7: Markings Area: | C7: ='General Information'!D28 -> 15000 | D7: S.F. | J7: No. of Slabs: | K7: =C5/((12.5*12.5)/9) -> 3840.0192
J8: Joint length: | K8: =K7*25+((K7/8)*12.5) -> 102000.51
A12: Item No. | B12: Pay Item | C12: Description | D12: Unit | E12: Qty | F12: Unit Cost | G12: Item Cost | J12: Item No. | K12: Pay Item | L12: Description | M12: Unit | N12: Qty | O12: Unit Cost | P12: Item Cost | R12: Item No. | S12: Pay Item | T12: Description | U12: Unit | V12: Qty | W12: Unit Cost | X12: Item Cost
A13: 1 | B13: =IF(C13="",0,VLOOKUP(C13,CHOOSE({1,2},Table2[Pay Item Description],Table2[Pay Item No.]),2,0)) -> 0 | D13: =IF(C13="","N/A",VLOOKUP(C13,CHOOSE({1,2},Table2[Pay Item Description],Table2[Units]),2,0)) -> N/A | F13: =IF(C13="","N/A",VLOOKUP(C13,CHOOSE({1,2},Table2[Pay Item Description],Table2[Unit Cost]),2,0)) -> N/A | G13: =IF(B13<>0,F13*E13,0) -> 0 | I13: =Pay_Items!D55 -> Joint Clean and Reseal, Concrete | J13: 1 | K13: =IF(L13="",0,VLOOKUP(L13,CHOOSE({1,2},Table2[Pay Item Description],Table2[Pay Item No.]),2,0)) -> P-605-5.1a | L13: =Pay_Items!D55 -> Joint Clean and Reseal, Concrete | M13: =IF(L13="","N/A",VLOOKUP(L13,CHOOSE({1,2},Table2[Pay Item Description],Table2[Units]),2,0)) -> L.F. | N13: =K8*'Maintenance Policies'!D37 -> 102000.51 | O13: =IF(L13="","N/A",VLOOKUP(L13,CHOOSE({1,2},Table2[Pay Item Description],Table2[Unit Cost]),2,0)) -> 7 | P13: =O13*N13 -> 714003.57 | R13: 1 | S13: =IF(T13="",0,VLOOKUP(T13,CHOOSE({1,2},Table2[Pay Item Description],Table2[Pay Item No.]),2,0)) -> P-101-5.5c | T13: =Pay_Items!D15 -> Slab Replacement, Concrete | U13: =IF(T13="","N/A",VLOOKUP(T13,CHOOSE({1,2},Table2[Pay Item Description],Table2[Units]),2,0)) -> S.Y. | V13: ='Maintenance Policies'!D41*C5 -> 1333.34 | W13: =IF(T13="","N/A",VLOOKUP(T13,CHOOSE({1,2},Table2[Pay Item Description],Table2[Unit Cost]),2,0)) -> 100 | X13: =W13*V13 -> 133334
A14: 2 | B14: =IF(C14="",0,VLOOKUP(C14,CHOOSE({1,2},Table2[Pay Item Description],Table2[Pay Item No.]),2,0)) -> 0 | D14: =IF(C14="","N/A",VLOOKUP(C14,CHOOSE({1,2},Table2[Pay Item Description],Table2[Units]),2,0)) -> N/A | F14: =IF(C14="","N/A",VLOOKUP(C14,CHOOSE({1,2},Table2[Pay Item Description],Table2[Unit Cost]),2,0)) -> N/A | G14: =IF(B14<>0,F14*E14,0) -> 0 | J14: 2 | K14: =VLOOKUP(L14,CHOOSE({1,2},Table2[Pay Item Description],Table2[Pay Item No.]),2,0) -> P-101-5.2c | L14: =Pay_Items!D8 -> Crack Seal, Concrete | M14: =IF(L14="","N/A",VLOOKUP(L14,CHOOSE({1,2},Table2[Pay Item Description],Table2[Units]),2,0)) -> L.F. | N14: ='Maintenance Policies'!D38*(C5*9) -> 1500.0075 | O14: =IF(L14="","N/A",VLOOKUP(L14,CHOOSE({1,2},Table2[Pay Item Description],Table2[Unit Cost]),2,0)) -> 8 | P14: =O14*N14 -> 12000.06 | R14: 2 | S14: =VLOOKUP(T14,CHOOSE({1,2},Table2[Pay Item Description],Table2[Pay Item No.]),2,0) -> P-101-5.5b | T14: =Pay_Items!D14 -> Full-Depth Repair, Concrete | U14: =IF(T14="","N/A",VLOOKUP(T14,CHOOSE({1,2},Table2[Pay Item Description],Table2[Units]),2,0)) -> S.Y. | V14: ='Maintenance Policies'!D42*C5 -> 200.001 | W14: =IF(T14="","N/A",VLOOKUP(T14,CHOOSE({1,2},Table2[Pay Item Description],Table2[Unit Cost]),2,0)) -> 120 | X14: =W14*V14 -> 24000.12
A15: 3 | B15: =IF(C15="",0,VLOOKUP(C15,CHOOSE({1,2},Table2[Pay Item Description],Table2[Pay Item No.]),2,0)) -> 0 | D15: =IF(C15="","N/A",VLOOKUP(C15,CHOOSE({1,2},Table2[Pay Item Description],Table2[Units]),2,0)) -> N/A | F15: =IF(C15="","N/A",VLOOKUP(C15,CHOOSE({1,2},Table2[Pay Item Description],Table2[Unit Cost]),2,0)) -> N/A | G15: =IF(B15<>0,F15*E15,0) -> 0 | J15: 3 | K15: =VLOOKUP(L15,CHOOSE({1,2},Table2[Pay Item Description],Table2[Pay Item No.]),2,0) -> P-101-5.5a | L15: =Pay_Items!D13 -> Spall Repair, Concrete | M15: =IF(L15="","N/A",VLOOKUP(L15,CHOOSE({1,2},Table2[Pay Item Description],Table2[Units]),2,0)) -> S.F. | N15: ='Maintenance Policies'!D39*(C5*9) -> 780.0039 | O15: =IF(L15="","N/A",VLOOKUP(L15,CHOOSE({1,2},Table2[Pay Item Description],Table2[Unit Cost]),2,0)) -> 60 | P15: =O15*N15 -> 46800.234 | R15: 3 | S15: =VLOOKUP(T15,CHOOSE({1,2},Table2[Pay Item Description],Table2[Pay Item No.]),2,0) -> P-101-5.5a | T15: =Pay_Items!D13 -> Spall Repair, Concrete | U15: =IF(T15="","N/A",VLOOKUP(T15,CHOOSE({1,2},Table2[Pay Item Description],Table2[Units]),2,0)) -> S.F. | V15: ='Maintenance Policies'!D43*(C5*9) -> 780.0039 | W15: =IF(T15="","N/A",VLOOKUP(T15,CHOOSE({1,2},Table2[Pay Item Description],Table2[Unit Cost]),2,0)) -> 60 | X15: =W15*V15 -> 46800.234
A16: 4 | B16: =IF(C16="",0,VLOOKUP(C16,CHOOSE({1,2},Table2[Pay Item Description],Table2[Pay Item No.]),2,0)) -> 0 | D16: =IF(C16="","N/A",VLOOKUP(C16,CHOOSE({1,2},Table2[Pay Item Description],Table2[Units]),2,0)) -> N/A | F16: =IF(C16="","N/A",VLOOKUP(C16,CHOOSE({1,2},Table2[Pay Item Description],Table2[Unit Cost]),2,0)) -> N/A | G16: =IF(B16<>0,F16*E16,0) -> 0 | J16: 4 | K16: =VLOOKUP(L16,CHOOSE({1,2},Table2[Pay Item Description],Table2[Pay Item No.]),2,0) -> P-101-5.5b | L16: =Pay_Items!D14 -> Full-Depth Repair, Concrete | M16: =IF(L16="","N/A",VLOOKUP(L16,CHOOSE({1,2},Table2[Pay Item Description],Table2[Units]),2,0)) -> S.Y. | N16: ='Maintenance Policies'!D40*C5 -> 200.001 | O16: =IF(L16="","N/A",VLOOKUP(L16,CHOOSE({1,2},Table2[Pay Item Description],Table2[Unit Cost]),2,0)) -> 120 | P16: =O16*N16 -> 24000.12 | R16: 4 | S16: =VLOOKUP(T16,CHOOSE({1,2},Table2[Pay Item Description],Table2[Pay Item No.]),2,0) -> P-101-5.2c | T16: =Pay_Items!D8 -> Crack Seal, Concrete | U16: =IF(T16="","N/A",VLOOKUP(T16,CHOOSE({1,2},Table2[Pay Item Description],Table2[Units]),2,0)) -> L.F. | V16: ='Maintenance Policies'!D44*(C5*9) -> 1800.009 | W16: =IF(T16="","N/A",VLOOKUP(T16,CHOOSE({1,2},Table2[Pay Item Description],Table2[Unit Cost]),2,0)) -> 8 | X16: =W16*V16 -> 14400.072
A17: 5 | B17: =IF(C17="",0,VLOOKUP(C17,CHOOSE({1,2},Table2[Pay Item Description],Table2[Pay Item No.]),2,0)) -> 0 | D17: =IF(C17="","N/A",VLOOKUP(C17,CHOOSE({1,2},Table2[Pay Item Description],Table2[Units]),2,0)) -> N/A | F17: =IF(C17="","N/A",VLOOKUP(C17,CHOOSE({1,2},Table2[Pay Item Description],Table2[Unit Cost]),2,0)) -> N/A | G17: =IF(B17<>0,F17*E17,0) -> 0 | O17: Subtotal | P17: =SUM(P13:P16) -> 796803.98 | R17: 5 | S17: =VLOOKUP(T17,CHOOSE({1,2},Table2[Pay Item Description],Table2[Pay Item No.]),2,0) -> P-605-5.1a | T17: =Pay_Items!D55 -> Joint Clean and Reseal, Concrete | U17: =IF(T17="","N/A",VLOOKUP(T17,CHOOSE({1,2},Table2[Pay Item Description],Table2[Units]),2,0)) -> L.F. | V17: ='Maintenance Policies'!D45*K8 -> 102000.51 | W17: =IF(T17="","N/A",VLOOKUP(T17,CHOOSE({1,2},Table2[Pay Item Description],Table2[Unit Cost]),2,0)) -> 7 | X17: =W17*V17 -> 714003.57
A18: 6 | B18: =IF(C18="",0,VLOOKUP(C18,CHOOSE({1,2},Table2[Pay Item Description],Table2[Pay Item No.]),2,0)) -> 0 | D18: =IF(C18="","N/A",VLOOKUP(C18,CHOOSE({1,2},Table2[Pay Item Description],Table2[Units]),2,0)) -> N/A | F18: =IF(C18="","N/A",VLOOKUP(C18,CHOOSE({1,2},Table2[Pay Item Description],Table2[Unit Cost]),2,0)) -> N/A | G18: =IF(B18<>0,F18*E18,0) -> 0 | L18: Mobilization | P18: =('General Information'!$D$36/100)*P17 -> 79680.398 | W18: Subtotal | X18: =SUM(X13:X17) -> 932538
A19: 7 | B19: =IF(C19="",0,VLOOKUP(C19,CHOOSE({1,2},Table2[Pay Item Description],Table2[Pay Item No.]),2,0)) -> 0 | D19: =IF(C19="","N/A",VLOOKUP(C19,CHOOSE({1,2},Table2[Pay Item Description],Table2[Units]),2,0)) -> N/A | F19: =IF(C19="","N/A",VLOOKUP(C19,CHOOSE({1,2},Table2[Pay Item Description],Table2[Unit Cost]),2,0)) -> N/A | G19: =IF(B19<>0,F19*E19,0) -> 0 | L19: Engineering | P19: =('General Information'!$D$37/100)*P17 -> 39840.199 | T19: Mobilization | X19: =('General Information'!$D$36/100)*X18 -> 93253.8
A20: 8 | B20: =IF(C20="",0,VLOOKUP(C20,CHOOSE({1,2},Table2[Pay Item Description],Table2[Pay Item No.]),2,0)) -> 0 | D20: =IF(C20="","N/A",VLOOKUP(C20,CHOOSE({1,2},Table2[Pay Item Description],Table2[Units]),2,0)) -> N/A | F20: =IF(C20="","N/A",VLOOKUP(C20,CHOOSE({1,2},Table2[Pay Item Description],Table2[Unit Cost]),2,0)) -> N/A | G20: =IF(B20<>0,F20*E20,0) -> 0 | O20: Total | P20: =SUM(P17:P19) -> 916324.58 | T20: Engineering | X20: =('General Information'!$D$37/100)*X18 -> 46626.9
A21: 9 | B21: =IF(C21="",0,VLOOKUP(C21,CHOOSE({1,2},Table2[Pay Item Description],Table2[Pay Item No.]),2,0)) -> 0 | D21: =IF(C21="","N/A",VLOOKUP(C21,CHOOSE({1,2},Table2[Pay Item Description],Table2[Units]),2,0)) -> N/A | F21: =IF(C21="","N/A",VLOOKUP(C21,CHOOSE({1,2},Table2[Pay Item Description],Table2[Unit Cost]),2,0)) -> N/A | G21: =IF(B21<>0,F21*E21,0) -> 0 | W21: Total | X21: =SUM(X18:X20) -> 1072418.7
A22: 10 | B22: =IF(C22="",0,VLOOKUP(C22,CHOOSE({1,2},Table2[Pay Item Description],Table2[Pay Item No.]),2,0)) -> 0 | D22: =IF(C22="","N/A",VLOOKUP(C22,CHOOSE({1,2},Table2[Pay Item Description],Table2[Units]),2,0)) -> N/A | F22: =IF(C22="","N/A",VLOOKUP(C22,CHOOSE({1,2},Table2[Pay Item Description],Table2[Unit Cost]),2,0)) -> N/A | G22: =IF(B22<>0,F22*E22,0) -> 0
A24: Subtotal | G24: =SUM(G13:G22) -> 0
B25: Mobilization | G25: =('General Information'!$D$36/100)*G24 -> 0
B26: Engineering | G26: =('General Information'!$D$37/100)*G24 -> 0
A27: Total | G27: =SUM(G24:G26) -> 0
A33: Net Present Worth
A34: PCC Reconstruction - Alternative 2 | I34: Hidden
B36: Item | C36: Year Applied | D36: Actual Cost | E36: Discounted Cost
B37: Initial Construction | C37: =C6 -> 2028 | D37: =G27 -> 0 | E37: =D37 -> 0 | K37: Year | L37: Direct Cost | M37: Indirect Cost | N37: Total Discounted Cost
B38: Maintenance 1 | C38: ='Maintenance Policies'!E37 -> 19 | D38: =P20 -> 916324.58 | E38: =IF(C38>'General Information'!$D$33,0,D38/(1+('General Information'!$D$34/100))^C38) -> 522567.1 | K38: =C6 -> 2028 | L38: =IF(K38-$C$6>'General Information'!$D$33,0,IF(K38=$C$6,$D$37,0)+SUMIFS($D$38:$D$42,$C$38:$C$42,K38-$C$6,$B$38:$B$42,"<>*Indirect*")) -> 0 | M38: =IF(K38-$C$6>'General Information'!$D$33,0,SUMIFS($D$38:$D$42,$C$38:$C$42,K38-$C$6,$B$38:$B$42,"*Indirect*")) -> 0 | N38: =IF(K38-$C$6>'General Information'!$D$33,0,IF(K38=$C$6,$E$37,0)+SUMIF($C$38:$C$42,K38-$C$6,$E$38:$E$42)) -> 0
B39: Maintenance 1 Indirect Cost | C39: ='Maintenance Policies'!E37 -> 19 | D39: =F2*F4 -> 32393.9 | E39: =IF(C39>'General Information'!$D$33,0,D39/(1+('General Information'!$D$34/100))^C39) -> 18473.789 | K39: =K38+1 -> 2029 | L39: =IF(K39-$C$6>'General Information'!$D$33,0,IF(K39=$C$6,$D$37,0)+SUMIFS($D$38:$D$42,$C$38:$C$42,K39-$C$6,$B$38:$B$42,"<>*Indirect*")) -> 0 | M39: =IF(K39-$C$6>'General Information'!$D$33,0,SUMIFS($D$38:$D$42,$C$38:$C$42,K39-$C$6,$B$38:$B$42,"*Indirect*")) -> 0 | N39: =IF(K39-$C$6>'General Information'!$D$33,0,IF(K39=$C$6,$E$37,0)+SUMIF($C$38:$C$42,K39-$C$6,$E$38:$E$42)) -> 0
B40: Rehabilitation 1 | C40: ='Maintenance Policies'!E41 -> 27 | D40: =X21 -> 1072418.7 | E40: =IF(C40>'General Information'!$D$33,0,D40/(1+('General Information'!$D$34/100))^C40) -> 482791.16 | K40: =K39+1 -> 2030 | L40: =IF(K40-$C$6>'General Information'!$D$33,0,IF(K40=$C$6,$D$37,0)+SUMIFS($D$38:$D$42,$C$38:$C$42,K40-$C$6,$B$38:$B$42,"<>*Indirect*")) -> 0 | M40: =IF(K40-$C$6>'General Information'!$D$33,0,SUMIFS($D$38:$D$42,$C$38:$C$42,K40-$C$6,$B$38:$B$42,"*Indirect*")) -> 0 | N40: =IF(K40-$C$6>'General Information'!$D$33,0,IF(K40=$C$6,$E$37,0)+SUMIF($C$38:$C$42,K40-$C$6,$E$38:$E$42)) -> 0
B41: Rehabilitation 1 Indirect Cost | C41: ='Maintenance Policies'!E41 -> 27 | D41: =F2*F5 -> 61548.41 | E41: =IF(C41>'General Information'!$D$33,0,D41/(1+('General Information'!$D$34/100))^C41) -> 27708.421 | K41: =K40+1 -> 2031 | L41: =IF(K41-$C$6>'General Information'!$D$33,0,IF(K41=$C$6,$D$37,0)+SUMIFS($D$38:$D$42,$C$38:$C$42,K41-$C$6,$B$38:$B$42,"<>*Indirect*")) -> 0 | M41: =IF(K41-$C$6>'General Information'!$D$33,0,SUMIFS($D$38:$D$42,$C$38:$C$42,K41-$C$6,$B$38:$B$42,"*Indirect*")) -> 0 | N41: =IF(K41-$C$6>'General Information'!$D$33,0,IF(K41=$C$6,$E$37,0)+SUMIF($C$38:$C$42,K41-$C$6,$E$38:$E$42)) -> 0
B42: Salvage | C42: ='General Information'!D33 -> 30 | D42: =-'Maintenance Policies'!D46*G27 -> 0 | E42: =IF(C42>'General Information'!$D$33,0,D42/(1+('General Information'!$D$34/100))^C42) -> 0 | K42: =K41+1 -> 2032 | L42: =IF(K42-$C$6>'General Information'!$D$33,0,IF(K42=$C$6,$D$37,0)+SUMIFS($D$38:$D$42,$C$38:$C$42,K42-$C$6,$B$38:$B$42,"<>*Indirect*")) -> 0 | M42: =IF(K42-$C$6>'General Information'!$D$33,0,SUMIFS($D$38:$D$42,$C$38:$C$42,K42-$C$6,$B$38:$B$42,"*Indirect*")) -> 0 | N42: =IF(K42-$C$6>'General Information'!$D$33,0,IF(K42=$C$6,$E$37,0)+SUMIF($C$38:$C$42,K42-$C$6,$E$38:$E$42)) -> 0
B43: Net Present Worth | E43: =SUM(E37:E42) -> 1051540.5 | K43: =K42+1 -> 2033 | L43: =IF(K43-$C$6>'General Information'!$D$33,0,IF(K43=$C$6,$D$37,0)+SUMIFS($D$38:$D$42,$C$38:$C$42,K43-$C$6,$B$38:$B$42,"<>*Indirect*")) -> 0 | M43: =IF(K43-$C$6>'General Information'!$D$33,0,SUMIFS($D$38:$D$42,$C$38:$C$42,K43-$C$6,$B$38:$B$42,"*Indirect*")) -> 0 | N43: =IF(K43-$C$6>'General Information'!$D$33,0,IF(K43=$C$6,$E$37,0)+SUMIF($C$38:$C$42,K43-$C$6,$E$38:$E$42)) -> 0
K44: =K43+1 -> 2034 | L44: =IF(K44-$C$6>'General Information'!$D$33,0,IF(K44=$C$6,$D$37,0)+SUMIFS($D$38:$D$42,$C$38:$C$42,K44-$C$6,$B$38:$B$42,"<>*Indirect*")) -> 0 | M44: =IF(K44-$C$6>'General Information'!$D$33,0,SUMIFS($D$38:$D$42,$C$38:$C$42,K44-$C$6,$B$38:$B$42,"*Indirect*")) -> 0 | N44: =IF(K44-$C$6>'General Information'!$D$33,0,IF(K44=$C$6,$E$37,0)+SUMIF($C$38:$C$42,K44-$C$6,$E$38:$E$42)) -> 0
K45: =K44+1 -> 2035 | L45: =IF(K45-$C$6>'General Information'!$D$33,0,IF(K45=$C$6,$D$37,0)+SUMIFS($D$38:$D$42,$C$38:$C$42,K45-$C$6,$B$38:$B$42,"<>*Indirect*")) -> 0 | M45: =IF(K45-$C$6>'General Information'!$D$33,0,SUMIFS($D$38:$D$42,$C$38:$C$42,K45-$C$6,$B$38:$B$42,"*Indirect*")) -> 0 | N45: =IF(K45-$C$6>'General Information'!$D$33,0,IF(K45=$C$6,$E$37,0)+SUMIF($C$38:$C$42,K45-$C$6,$E$38:$E$42)) -> 0
K46: =K45+1 -> 2036 | L46: =IF(K46-$C$6>'General Information'!$D$33,0,IF(K46=$C$6,$D$37,0)+SUMIFS($D$38:$D$42,$C$38:$C$42,K46-$C$6,$B$38:$B$42,"<>*Indirect*")) -> 0 | M46: =IF(K46-$C$6>'General Information'!$D$33,0,SUMIFS($D$38:$D$42,$C$38:$C$42,K46-$C$6,$B$38:$B$42,"*Indirect*")) -> 0 | N46: =IF(K46-$C$6>'General Information'!$D$33,0,IF(K46=$C$6,$E$37,0)+SUMIF($C$38:$C$42,K46-$C$6,$E$38:$E$42)) -> 0
K47: =K46+1 -> 2037 | L47: =IF(K47-$C$6>'General Information'!$D$33,0,IF(K47=$C$6,$D$37,0)+SUMIFS($D$38:$D$42,$C$38:$C$42,K47-$C$6,$B$38:$B$42,"<>*Indirect*")) -> 0 | M47: =IF(K47-$C$6>'General Information'!$D$33,0,SUMIFS($D$38:$D$42,$C$38:$C$42,K47-$C$6,$B$38:$B$42,"*Indirect*")) -> 0 | N47: =IF(K47-$C$6>'General Information'!$D$33,0,IF(K47=$C$6,$E$37,0)+SUMIF($C$38:$C$42,K47-$C$6,$E$38:$E$42)) -> 0
K48: =K47+1 -> 2038 | L48: =IF(K48-$C$6>'General Information'!$D$33,0,IF(K48=$C$6,$D$37,0)+SUMIFS($D$38:$D$42,$C$38:$C$42,K48-$C$6,$B$38:$B$42,"<>*Indirect*")) -> 0 | M48: =IF(K48-$C$6>'General Information'!$D$33,0,SUMIFS($D$38:$D$42,$C$38:$C$42,K48-$C$6,$B$38:$B$42,"*Indirect*")) -> 0 | N48: =IF(K48-$C$6>'General Information'!$D$33,0,IF(K48=$C$6,$E$37,0)+SUMIF($C$38:$C$42,K48-$C$6,$E$38:$E$42)) -> 0
K49: =K48+1 -> 2039 | L49: =IF(K49-$C$6>'General Information'!$D$33,0,IF(K49=$C$6,$D$37,0)+SUMIFS($D$38:$D$42,$C$38:$C$42,K49-$C$6,$B$38:$B$42,"<>*Indirect*")) -> 0 | M49: =IF(K49-$C$6>'General Information'!$D$33,0,SUMIFS($D$38:$D$42,$C$38:$C$42,K49-$C$6,$B$38:$B$42,"*Indirect*")) -> 0 | N49: =IF(K49-$C$6>'General Information'!$D$33,0,IF(K49=$C$6,$E$37,0)+SUMIF($C$38:$C$42,K49-$C$6,$E$38:$E$42)) -> 0
K50: =K49+1 -> 2040 | L50: =IF(K50-$C$6>'General Information'!$D$33,0,IF(K50=$C$6,$D$37,0)+SUMIFS($D$38:$D$42,$C$38:$C$42,K50-$C$6,$B$38:$B$42,"<>*Indirect*")) -> 0 | M50: =IF(K50-$C$6>'General Information'!$D$33,0,SUMIFS($D$38:$D$42,$C$38:$C$42,K50-$C$6,$B$38:$B$42,"*Indirect*")) -> 0 | N50: =IF(K50-$C$6>'General Information'!$D$33,0,IF(K50=$C$6,$E$37,0)+SUMIF($C$38:$C$42,K50-$C$6,$E$38:$E$42)) -> 0
K51: =K50+1 -> 2041 | L51: =IF(K51-$C$6>'General Information'!$D$33,0,IF(K51=$C$6,$D$37,0)+SUMIFS($D$38:$D$42,$C$38:$C$42,K51-$C$6,$B$38:$B$42,"<>*Indirect*")) -> 0 | M51: =IF(K51-$C$6>'General Information'!$D$33,0,SUMIFS($D$38:$D$42,$C$38:$C$42,K51-$C$6,$B$38:$B$42,"*Indirect*")) -> 0 | N51: =IF(K51-$C$6>'General Information'!$D$33,0,IF(K51=$C$6,$E$37,0)+SUMIF($C$38:$C$42,K51-$C$6,$E$38:$E$42)) -> 0
...

Sheet Overview
E2: Tennessee Department of Transportation
E3: Aeronautics Division
E4: 7335 Centennial Boulevard
E5: Nashville, Tennessee 37209
E6: 615-741-3208
E7: https://www.tn.gov/tdot/aeronautics.html
B9: Overview:

Sheet Instructions
E2: Tennessee Department of Transportation
E3: Aeronautics Division
E4: 7335 Centennial Boulevard
E5: Nashville, Tennessee 37209
E6: 615-741-3208
E7: https://www.tn.gov/tdot/aeronautics.html
B9: Instructions:

Sheet General Information
K7: Hidden
B8: Airport Information: | L8: Name | M8: ID | N8: City | O8: County | P8: Region | Q8: Owner | S8: Branch Use
C9: Airport Name: | D9: Outlaw Field | N9: N/A | O9: N/A
C10: Airport ID: | D10: =IF(D9="","N/A",VLOOKUP(Airport_Name,Table17[],2)) -> CKV | L10: Abernathy Field | M10: GZS | N10: Pulaski | O10: Giles | P10: Middle | S10: Runway
C11: City: | D11: =IF(D9="","N/A",VLOOKUP(Airport_Name,Table17[],3)) -> Clarksville | L11: Arnold Field | M11: M31 | N11: Halls | O11: Lauderdale | P11: West | S11: Taxiway
C12: Airport Owner: | D12: =IF(D9="","N/A",VLOOKUP(Airport_Name,Table17[],6)) -> 0 | L12: Beech River Regional Airport | M12: PVE | N12: Lexington/Parsons | O12: Henderson | P12: West | S12: Apron
C13: State Region: | D13: =IF(D9="","N/A",VLOOKUP(Airport_Name,Table17[],5)) -> Middle | L13: Benton County Airport | M13: 0M4 | N13: Camden | O13: Benton | P13: West
C14: Design Consultant: | D14: ARA | L14: Bomar Field-Shelbyville Municipal Airport | M14: SYI | N14: Shelbyville | O14: Bedford | P14: Middle
C15: Project Number: | D15: 5936 | L15: Carroll County Airport | M15: HZD | N15: Huntingdon | O15: Carroll | P15: West | S15: Markings Type
C16: Project Name: | D16: Runway 17-35 Reconstruction | L16: Centerville Municipal Airport | M16: GHM | N16: Centerville | O16: Hickman | P16: Middle
C17: Date of LCCA: | L17: Charles W. Baker Field | M17: 2M8 | N17: Millington | O17: Shelby | P17: West | S17: Reflective
L18: Chilhowee Gliderport | M18: 92A | N18: Benton | O18: Polk | P18: East | S18: Non-Reflective
L19: Cleveland Regional Jetport | M19: RZR | N19: Cleveland | O19: Bradley | P19: East
B20: Project Information: | L20: Collegedale Municipal Airport | M20: FGU | N20: Collegedale | O20: Hamilton | P20: East
C21: Branch Type: | D21: Runway | L21: Colonel Tommy C. Stiner-Campbell County Airport | M21: JAU | N21: Jacksboro | O21: Campbell | P21: East | S21: Weight Category
C22: Branch Name: | D22: Runway 17-35 | L22: Covington Municipal Airport | M22: M04 | N22: Covington | O22: Tipton | P22: West
C23: Project Type: | D23: Reconstruction | L23: Crossville Memorial Airport/Whitson Field | M23: CSV | N23: Crossville | O23: Cumberland | P23: East | S23: < 60,000 lbs
C24: Project Description: | D24: Full-depth reconstruction, 6,000 x 100 ft | L24: Dallas Bay Skypark Airport | M24: 1A0 | N24: Chattanooga | O24: Hamilton | P24: East | S24: > 60,000 to < 100,000 lbs
C25: Intial Construction Year: | D25: 2028 | L25: Dickson Municipal Airport | M25: M02 | N25: Dickson | O25: Dickson | P25: Middle | S25: > 100,000 lbs
C26: Mainline Area, S.Y.: | D26: 66667 | L26: Dyersburg Municipal Airport | M26: DYR | N26: Dyersburg | O26: Dyer | P26: West
C27: Shoulder Area, S.Y.: | D27: 0 | L27: Elizabethton Municipal Airport | M27: 0A9 | N27: Elizabethton | O27: Carter | P27: East
C28: Markings, S.F.: | D28: 15000 | L28: Ellington Airport | M28: LUG | N28: Lewisburg | O28: Marshall | P28: Middle
C29: Markings, Type: | D29: Reflective | L29: Everett-Stewart Airport | M29: UCY | N29: Union City | O29: Obion | P29: West
L30: Fayette County Airport | M30: FYE | N30: Somerville | O30: Fayette | P30: West
L31: Fayetteville Municipal Airport | M31: FYM | N31: Fayetteville | O31: Lincoln | P31: Middle
B32: LCCA Parameters: | L32: Franklin County Airport | M32: UOS | N32: Sewanee | O32: Franklin | P32: Middle
C33: Analysis Period, years: | D33: 30 | L33: Gatlinburg-Pigeon Forge Airport | M33: GKT | N33: Sevierville | O33: Sevier | P33: East
C34: Discount Rate, percent: | D34: 3 | L34: General Dewitt Spain Airport | M34: M01 | N34: Memphis | O34: Shelby | P34: West
C35: Salvage Value, $: | D35: Remaining service life at end of analysis period (as percent of cost) | L35: Gibson County Airport | M35: TGC | N35: Trenton | O35: Gibson | P35: West
C36: Mobilization, percent: | D36: 10 | L36: Greeneville-Green County Municipal Airport | M36: GCY | N36: Greeneville | O36: Greene | P36: East
C37: Engineering, percent: | D37: 5 | L37: Hassell-Carroll Field | M37: M29 | N37: Clifton | O37: Wayne | P37: Middle
C38: Account Indirect Cost (Yes/No) | D38: Yes | L38: Hawkins County Airport | M38: RVN | N38: Rogersville | O38: Hawkins | P38: East
C39: Airport Daily Revenue | D39: =IF(D38<>"Yes","",IF(COUNTIF(RevenueData!$A:$A,$D$10)=0,"Missing Airport Revenue",SUMIF(RevenueData!$A:$A,$D$10,RevenueData!$B:$B)+SUMIF(RevenueData!$A:$A,$D$10,RevenueData!$C:$C)+SUMIF(RevenueData!$A:$A,$D$10,RevenueData!$D:$D)+SUMIF(RevenueData!$A:$A,$D$10,RevenueData!$E:$E)+SUMIF(RevenueData!$A:$A,$D$10,RevenueData!$F:$F)+SUMIF(RevenueData!$A:$A,$D$10,RevenueData!$G:$G)+SUMIF(RevenueData!$A:$A,$D$10,RevenueData!$H:$H))) -> 3239.39 | L39: Henry County Airport | M39: PHT | N39: Paris | O39: Henry | P39: West
L40: Houston County Airport | M40: M93 | N40: McKinnon | O40: Houston | P40: Middle
B41: Alternative Setup: | L41: Humboldt Municipal Airport | M41: M53 | N41: Humboldt | O41: Gibson | P41: West
L42: Humphreys County Airport | M42: 0M5 | N42: Waverly | O42: Humphreys | P42: Middle
L43: Jackson County Airport | M43: 1A7 | N43: Gainesboro | O43: Jackson | P43: Middle
B44: LCCA Summary: | D44: =HYPERLINK("#Summary!G1","View Summary ►") -> View Summary ► | L44: James Tucker-Perry County Airport | M44: M15 | N44: Linden | O44: Perry | P44: Middle
L45: Jamestown Municipal Airport | M45: 2A1 | N45: Jamestown | O45: Fentress | P45: Middle
L46: John A. Baker Field | M46: 0M3 | N46: Hohenwald | O46: Lewis | P46: Middle
...

Sheet Pay_Items
G1: Average Pay Item Unit Cost
A2: Division | B2: Division Type | C2: Pay Item No. | D2: Pay Item Description | E2: Units | F2: Unit Cost | G2: Middle | H2: West | I2: East
B3: Default | E3: N/A | F3: N/A
A4: Part 3 – Sitework | B4: Sitework | C4: P-101-5.1a | D4: Pavement Removal, Asphalt | E4: S.Y. | F4: 4.2 | J4: Thickness adjustment or multiple
B5: Sitework | C5: P-101-5.1b | D5: Pavement Removal, Concrete | E5: S.Y. | J5: Thickness adjustment or multiple
B6: Sitework | C6: P-101-5.2a | D6: Crack Repair (Type I), Asphalt | E6: L.F. | F6: 4
B7: Sitework | C7: P-101-5.2b | D7: Crack Repair (Type II), Asphalt | E7: L.F. | F7: 6.5
B8: Sitework | C8: P-101-5.2c | D8: Crack Seal, Concrete | E8: L.F. | F8: 8
B9: Sitework | C9: P-101-5.2d | D9: Crack Repair, Concrete | E9: L.F. | F9: 8.5
B10: Sitework | C10: P-101-5.3 | D10: Markings Removal | E10: S.F. | F10: =7/9 -> 0.77777778
B11: Sitework | C11: P-101-5.4a | D11: Spall Repair, Asphalt | E11: S.F. | F11: 8.5 | J11: Thickness adjustment or multiple
B12: Sitework | C12: P-101-5.4b | D12: Full-Depth Repair, Asphalt | E12: S.F. | J12: Assumed Section: 4-inch HMA; 4-inch P-209
B13: Sitework | C13: P-101-5.5a | D13: Spall Repair, Concrete | E13: S.F. | F13: 60 | J13: Thickness adjustment or multiple
B14: Sitework | C14: P-101-5.5b | D14: Full-Depth Repair, Concrete | E14: S.Y. | F14: 120 | J14: Thickness adjustment or multiple
B15: Sitework | C15: P-101-5.5c | D15: Slab Replacement, Concrete | E15: S.Y. | F15: 100
B16: Sitework | C16: P-101-5.6 | D16: Cold Milling | E16: S.Y. | F16: =10/2 -> 5 | J16: Thickness adjustment or multiple
B17: Sitework | C17: P-152-4.1 | D17: Unclassified Excavation | E17: C.Y.
B18: Sitework | C18: P-152-4.2 | D18: Embankment In-Place | E18: C.Y.
B19: Sitework | C19: P-154-5.1 | D19: Subbase Course | E19: C.Y. | F19: 55
B20: Sitework | C20: P-154-5.2 | D20: Separation Geotextile (P-154) | E20: S.Y.
B21: Sitework | C21: P-155-8.1 | D21: Lime Treated subgrade | E21: S.Y. | F21: 10 | J21: Thickness adjustment or multiple
B22: Sitework | C22: P-156-8.1 | D22: Cement-Treated Subgrade | E22: S.Y. | J22: Thickness adjustment or multiple
B23: Sitework | C23: P-157-8.1a | D23: Cement Kiln Dust-Treated Subgrade | E23: S.Y. | J23: Thickness adjustment or multiple
B24: Sitework | C24: P-157-8.1b | D24: Lime Kiln Dust-Treated Subgrade | E24: S.Y. | J24: Thickness adjustment or multiple
B25: Sitework | C25: P-158-8.1 | D25: Fly Ash-Treated Subgrade | E25: S.Y. | J25: Thickness adjustment or multiple
A26: Part 4 – Base Courses | B26: Base Course | C26: P-207-5.1 | D26: In-Place Full Depth Reclamation (FDR) Recycled Asphalt Aggregate Base Course | E26: S.Y. | J26: Thickness adjustment or multiple
B27: Base Course | C27: P-208-5.1 | D27: Aggregate Base Course | E27: C.Y.
B28: Base Course | C28: P-208-5.2 | D28: Separation Geotextile (P-208) | E28: S.Y.
B29: Base Course | C29: P-209-5.1 | D29: Crushed Aggregate Base Course | E29: C.Y. | F29: 65
B30: Base Course | C30: P-209-5.2 | D30: Separation Geotextile (P-209) | E30: S.Y.
B31: Base Course | C31: P-219-5.1 | D31: Recycled Concrete Aggregate Base Course | E31: C.Y.
B32: Base Course | C32: P-219-5.2 | D32: Separation Geotextile (P-219) | E32: S.Y.
B33: Base Course | C33: P-220-6.1 | D33: Cement-Treated Soil Base Course | E33: S.Y. | J33: Thickness adjustment or multiple
A34: Part 5 – Stabilized Base Courses | B34: Stabilized Base Course | C34: P-304-8.1 | D34: Cement-Treated Base Course | E34: C.Y. | J34: If S.Y., then thickness adjustment
B35: Stabilized Base Course | C35: P-306-8.1 | D35: Lean Concrete Base Course | E35: C.Y. | J35: If S.Y., then thickness adjustment
B36: Stabilized Base Course | C36: P-307-7.1 | D36: Cement-Treated Permeable Base Course (CTPB) | E36: C.Y. | J36: If S.Y., then thickness adjustment
A37: Part 6 – Flexible Pavements | B37: Flexible Pavement | C37: P-401-8.1a | D37: Asphalt Surface Course | E37: TON | F37: 130
B38: Flexible Pavement | C38: P-401-8.1b | D38: Asphalt Base Course | E38: TON | F38: 120
B39: Flexible Pavement | C39: P-401-8.1c | D39: Asphalt Leveling Course | E39: TON | F39: 110
B40: Flexible Pavement | C40: P-403-8.1a | D40: Asphalt Mixture Surface Course | E40: TON
...

Sheet Database
A1: Alternative List
A3: Name | B3: Type | C3: Description | D3: Alt Worksheet Name
A4: Alternative 1 | B4: HMA-New | C4: New HMA | D4: Alt 1 (New HMA)
A5: Alternative 2 | B5: PCC-New | C5: New PCC | D5: Alt 2 (New PCC)

Sheet Maintenance Policies
B8: Table 1. New HMA maintenance policies.
B9: Asphalt Maintenance | C9: Maintenance Item | D9: Rate | E9: Year Applied
B10: Maintenance 1 | C10: Surface treatment, SYD | D10: 1 | E10: 4
C11: Paint markings, SFT | D11: 1
B12: Maintenance 2 | C12: Surface treatment, SYD | D12: 1 | E12: 8
C13: Paint markings, SFT | D13: 1
B14: Maintenance 3 | C14: Patching: 0.75% of area | D14: 0.0075 | E14: 12
C15: Crack sealing: 3.25% of area as linear feet | D15: 0.0325
C16: Surface treatment: 100% of area | D16: 1
C17: Paint markings: 100% of markings | D17: 1
B18: Maintenance 4 | C18: Patching: 1.00% of area | D18: 0.01 | E18: 16
C19: Crack sealing: 3.50% of area as linear feet | D19: 0.035
C20: Surface treatment: 100% of area | D20: 1
C21: Paint markings: 100% of markings | D21: 1
B22: Rehabilitation 1 | C22: Mill and overlay: 4-inch cold mill, tack coat, and asphalt overlay | D22: 1 | E22: 20
C23: Pre-overlay crack repair: 1.5% of area as linear feet | D23: 0.015
C24: Pre-overlay patching: 0.5% of area | D24: 0.005
C25: Paint markings: 100% of markings | D25: 1
B26: Maintenance 5 | C26: Surface treatment: 100% of area | D26: 1 | E26: 24
C27: Paint markings: 100% of markings | D27: 1
B28: Maintenance 6 | C28: Patching: 1.25% of area | D28: 0.0125 | E28: 28
C29: Crack sealing: 4.0% of area as linear feet | D29: 0.04
C30: Surface treatment: 100% of area | D30: 1
C31: Paint markings: 100% of markings | D31: 1
B32: Salvage | C32: Salvage value: 2 years (0.125) of mill and overlay | D32: 0.125 | E32: 30
B35: Table 2. New PCC maintenance policies.
B36: Concrete Maintenance | C36: Maintenance Item | D36: Rate | E36: Year Applied
B37: Maintenance 1 | C37: Joint resealing: 100% of joints | D37: 1 | E37: 19
C38: Crack sealing: 0.25% of area as linear feet | D38: 0.0025
C39: Partial-depth patching: 0.13% of area | D39: 0.0013
C40: Full-depth patching: 0.30% of area | D40: 0.003
B41: Rehabilitation 1 | C41: Slab replacements: 2% of area | D41: 0.02 | E41: 27
C42: Full-depth patching: 0.30% of area | D42: 0.003
C43: Partial-depth patching: 0.13% of area | D43: 0.0013
C44: Crack sealing: 0.30% of area as linear feet | D44: 0.003
C45: Joint sealing: 100% of joints | D45: 1
B46: Salvage | C46: Salvage value: 10 years (0.25) of initial construction | D46: 0.25 | E46: 30
B49: Table 3. First HMA Overlay maintenance policies.
B50: Asphalt Maintenance | C50: Maintenance Item | D50: Rate | E50: Year Applied
B51: Maintenance 1 | C51: Surface treatment: 100% of area | D51: 1 | E51: 4
...

Sheet TMP(NewHMA)_IndirectCost
I1: Hidden
A2: Initial Construction Costs: | E2: Average Daily Revenue: | F2: =IF('General Information'!$D$38="Yes",SUMIF(RevenueData!$A:$A,'General Information'!$D$10,RevenueData!$B:$B)+SUMIF(RevenueData!$A:$A,'General Information'!$D$10,RevenueData!$C:$C)+SUMIF(RevenueData!$A:$A,'General Information'!$D$10,RevenueData!$D:$D)+SUMIF(RevenueData!$A:$A,'General Information'!$D$10,RevenueData!$E:$E)+SUMIF(RevenueData!$A:$A,'General Information'!$D$10,RevenueData!$F:$F)+SUMIF(RevenueData!$A:$A,'General Information'!$D$10,RevenueData!$G:$G)+SUMIF(RevenueData!$A:$A,'General Information'!$D$10,RevenueData!$H:$H),0) -> 3239.39 | G2: =IF(AND('General Information'!$D$38="Yes",F2=0),"No revenue data for this airport - lost revenue set to $0. Contact Aeronautics.","") | J2: Maintenance 1 | R2: Maintenance 2 | Z2: Maintenance 3 | AH2: Maintenance 4 | AP2: Rehabilitation 1 | AX2: Maintenance 5 | BF2: Maintenance 6
A4: Pavement Type: | C4: New HMA | E4: Maintenance 1 Duration (Days) | F4: =ROUNDUP((C5/15000),0)+ROUNDUP((C8/20000),0)+ROUNDUP((C8/50000),0) -> 7
A5: Mainline Pavement Area: | C5: ='General Information'!D26 -> 66667 | D5: S.Y. | E5: Maintenance 2 Duration (Days) | F5: =ROUNDUP((C5/15000),0)+ROUNDUP((C8/20000),0)+ROUNDUP((C8/50000),0) -> 7
A6: Initial Construction Year: | C6: ='General Information'!D25 -> 2028 | E6: Maintenance 3 Duration (Days) | F6: =ROUNDUP((C5/15000),0)+ROUNDUP((C8/20000),0)+ROUNDUP((C8/50000),0)+ROUNDUP((C5*'Maintenance Policies'!D15/10000),0)+ROUNDUP((C5*'Maintenance Policies'!D14/5000),0) -> 9 | AP6: Mill and overlay: | AQ6: 2 | AR6: inches
A7: Asphalt Surface Treatment Type: | C7: Emulsified Asphalt Surface Treatment | D7: Select alternative treatment, if planned. | E7: Maintenance 4 Duration (Days) | F7: =ROUNDUP((C5/15000),0)+ROUNDUP((C8/20000),0)+ROUNDUP((C8/50000),0)+ROUNDUP((C5*'Maintenance Policies'!D18/10000),0)+ROUNDUP((C5*'Maintenance Policies'!D19/5000),0) -> 9 | AP7: Asphalt: | AQ7: 120 | AR7: lbs/SY-in
A8: Markings Area: | C8: ='General Information'!D28 -> 15000 | D8: S.F. | E8: Rehabilitation 1 Duration (Days) | F8: =ROUNDUP((C5/3800),0)+ROUNDUP((C8/50000),0) -> 19
E9: Maintenance 5 Duration (Days) | F9: =ROUNDUP((C5/15000),0)+ROUNDUP((C8/20000),0)+ROUNDUP((C8/50000),0) -> 7 | AP9: Tack Coat Application | AQ9: 0.1 | AR9: gal/S.Y.
E10: Maintenance 6 Duration (Days) | F10: =ROUNDUP((C5/15000),0)+ROUNDUP((C8/20000),0)+ROUNDUP((C8/50000),0)+ROUNDUP((C5*'Maintenance Policies'!D28/10000),0)+ROUNDUP((C5*'Maintenance Policies'!D29/5000),0) -> 9
A12: Item No. | B12: Pay Item | C12: Description | D12: Unit | E12: Qty | F12: Unit Cost | G12: Item Cost | J12: Item No. | K12: Pay Item | L12: Description | M12: Unit | N12: Qty | O12: Unit Cost | P12: Item Cost | R12: Item No. | S12: Pay Item | T12: Description | U12: Unit | V12: Qty | W12: Unit Cost | X12: Item Cost | Z12: Item No. | AA12: Pay Item | AB12: Description | AC12: Unit | AD12: Qty | AE12: Unit Cost | AF12: Item Cost | AH12: Item No. | AI12: Pay Item | AJ12: Description | AK12: Unit | AL12: Qty | AM12: Unit Cost | AN12: Item Cost | AP12: Item No. | AQ12: Pay Item | AR12: Description | AS12: Unit | AT12: Qty | AU12: Unit Cost | AV12: Item Cost | AX12: Item No. | AY12: Pay Item | AZ12: Description | BA12: Unit | BB12: Qty | BC12: Unit Cost | BD12: Item Cost | BF12: Item No. | BG12: Pay Item | BH12: Description | BI12: Unit | BJ12: Qty | BK12: Unit Cost | BL12: Item Cost
A13: 1 | B13: =IF(C13="",0,VLOOKUP(C13,CHOOSE({1,2},Table2[Pay Item Description],Table2[Pay Item No.]),2,0)) -> 0 | D13: =IF(C13="","N/A",VLOOKUP(C13,CHOOSE({1,2},Table2[Pay Item Description],Table2[Units]),2,0)) -> N/A | F13: =IF(C13="","N/A",VLOOKUP(C13,CHOOSE({1,2},Table2[Pay Item Description],Table2[Unit Cost]),2,0)) -> N/A | G13: =IF(B13<>0,F13*E13,0) -> 0 | J13: 1 | K13: =IF(L13="",0,VLOOKUP(L13,CHOOSE({1,2},Table2[Pay Item Description],Table2[Pay Item No.]),2,0)) -> P-608-8.1 | L13: =C7 -> Emulsified Asphalt Surface Treatment | M13: =VLOOKUP(L13,CHOOSE({1,2},Table2[Pay Item Description],Table2[Units]),2,0) -> S.Y. | N13: ='Maintenance Policies'!D10*$C$5 -> 66667 | O13: =IF(L13="","N/A",VLOOKUP(L13,CHOOSE({1,2},Table2[Pay Item Description],Table2[Unit Cost]),2,0)) -> 4 | P13: =O13*N13 -> 266668 | R13: 1 | S13: =IF(T13="",0,VLOOKUP(T13,CHOOSE({1,2},Table2[Pay Item Description],Table2[Pay Item No.]),2,0)) -> P-608-8.1 | T13: =C7 -> Emulsified Asphalt Surface Treatment | U13: =VLOOKUP(T13,CHOOSE({1,2},Table2[Pay Item Description],Table2[Units]),2,0) -> S.Y. | V13: ='Maintenance Policies'!D12*$C$5 -> 66667 | W13: =IF(T13="","N/A",VLOOKUP(T13,CHOOSE({1,2},Table2[Pay Item Description],Table2[Unit Cost]),2,0)) -> 4 | X13: =W13*V13 -> 266668 | Z13: 1 | AA13: =IF(AB13="",0,VLOOKUP(AB13,CHOOSE({1,2},Table2[Pay Item Description],Table2[Pay Item No.]),2,0)) -> P-101-5.4a | AB13: =Pay_Items!D11 -> Spall Repair, Asphalt | AC13: =IF(AB13="","N/A",VLOOKUP(AB13,CHOOSE({1,2},Table2[Pay Item Description],Table2[Units]),2,0)) -> S.F. | AD13: ='Maintenance Policies'!D14*($C$5*9) -> 4500.0225 | AE13: =IF(AB13="","N/A",VLOOKUP(AB13,CHOOSE({1,2},Table2[Pay Item Description],Table2[Unit Cost]),2,0)) -> 8.5 | AF13: =AE13*AD13 -> 38250.191 | AH13: 1 | AI13: =IF(AJ13="",0,VLOOKUP(AJ13,CHOOSE({1,2},Table2[Pay Item Description],Table2[Pay Item No.]),2,0)) -> P-101-5.4a | AJ13: =Pay_Items!D11 -> Spall Repair, Asphalt | AK13: =IF(AJ13="","N/A",VLOOKUP(AJ13,CHOOSE({1,2},Table2[Pay Item Description],Table2[Units]),2,0)) -> S.F. | AL13: ='Maintenance Policies'!D18*($C$5*9) -> 6000.03 | AM13: =IF(AJ13="","N/A",VLOOKUP(AJ13,CHOOSE({1,2},Table2[Pay Item Description],Table2[Unit Cost]),2,0)) -> 8.5 | AN13: =AM13*AL13 -> 51000.255 | AP13: 1 | AQ13: =IF(AR13="",0,VLOOKUP(AR13,CHOOSE({1,2},Table2[Pay Item Description],Table2[Pay Item No.]),2,0)) -> P-101-5.6 | AR13: =Pay_Items!D16 -> Cold Milling | AS13: =IF(AR13="","N/A",VLOOKUP(AR13,CHOOSE({1,2},Table2[Pay Item Description],Table2[Units]),2,0)) -> S.Y. | AT13: ='Maintenance Policies'!D22*$C$5 -> 66667 | AU13: =IF(AR13="","N/A",VLOOKUP(AR13,CHOOSE({1,2},Table2[Pay Item Description],Table2[Unit Cost]),2,0)) -> 5 | AV13: =AU13*AT13 -> 333335 | AX13: 1 | AY13: =IF(AZ13="",0,VLOOKUP(AZ13,CHOOSE({1,2},Table2[Pay Item Description],Table2[Pay Item No.]),2,0)) -> P-608-8.1 | AZ13: =C7 -> Emulsified Asphalt Surface Treatment | BA13: =IF(AZ13="","N/A",VLOOKUP(AZ13,CHOOSE({1,2},Table2[Pay Item Description],Table2[Units]),2,0)) -> S.Y. | BB13: ='Maintenance Policies'!D26*$C$5 -> 66667 | BC13: =IF(AZ13="","N/A",VLOOKUP(AZ13,CHOOSE({1,2},Table2[Pay Item Description],Table2[Unit Cost]),2,0)) -> 4 | BD13: =BC13*BB13 -> 266668 | BF13: 1 | BG13: =IF(BH13="",0,VLOOKUP(BH13,CHOOSE({1,2},Table2[Pay Item Description],Table2[Pay Item No.]),2,0)) -> P-101-5.4a | BH13: =Pay_Items!D11 -> Spall Repair, Asphalt | BI13: =IF(BH13="","N/A",VLOOKUP(BH13,CHOOSE({1,2},Table2[Pay Item Description],Table2[Units]),2,0)) -> S.F. | BJ13: ='Maintenance Policies'!D28*($C$5*9) -> 7500.0375 | BK13: =IF(BH13="","N/A",VLOOKUP(BH13,CHOOSE({1,2},Table2[Pay Item Description],Table2[Unit Cost]),2,0)) -> 8.5 | BL13: =BK13*BJ13 -> 63750.319
A14: 2 | B14: =IF(C14="",0,VLOOKUP(C14,CHOOSE({1,2},Table2[Pay Item Description],Table2[Pay Item No.]),2,0)) -> 0 | D14: =IF(C14="","N/A",VLOOKUP(C14,CHOOSE({1,2},Table2[Pay Item Description],Table2[Units]),2,0)) -> N/A | F14: =IF(C14="","N/A",VLOOKUP(C14,CHOOSE({1,2},Table2[Pay Item Description],Table2[Unit Cost]),2,0)) -> N/A | G14: =IF(B14<>0,F14*E14,0) -> 0 | J14: 2 | K14: =IF(L14="",0,VLOOKUP(L14,CHOOSE({1,2},Table2[Pay Item Description],Table2[Pay Item No.]),2,0)) -> P-101-5.3 | L14: =Pay_Items!D10 -> Markings Removal | M14: =IF(L14="","N/A",VLOOKUP(L14,CHOOSE({1,2},Table2[Pay Item Description],Table2[Units]),2,0)) -> S.F. | N14: ='Maintenance Policies'!D10*$C$8 -> 15000 | O14: =IF(L14="","N/A",VLOOKUP(L14,CHOOSE({1,2},Table2[Pay Item Description],Table2[Unit Cost]),2,0)) -> 0.77777778 | P14: =O14*N14 -> 11666.667 | R14: 2 | S14: =IF(T14="",0,VLOOKUP(T14,CHOOSE({1,2},Table2[Pay Item Description],Table2[Pay Item No.]),2,0)) -> P-101-5.3 | T14: =Pay_Items!D10 -> Markings Removal | U14: =IF(T14="","N/A",VLOOKUP(T14,CHOOSE({1,2},Table2[Pay Item Description],Table2[Units]),2,0)) -> S.F. | V14: ='Maintenance Policies'!D12*$C$8 -> 15000 | W14: =IF(T14="","N/A",VLOOKUP(T14,CHOOSE({1,2},Table2[Pay Item Description],Table2[Unit Cost]),2,0)) -> 0.77777778 | X14: =W14*V14 -> 11666.667 | Z14: 2 | AA14: =IF(AB14="",0,VLOOKUP(AB14,CHOOSE({1,2},Table2[Pay Item Description],Table2[Pay Item No.]),2,0)) -> P-101-5.2a | AB14: =Pay_Items!D6 -> Crack Repair (Type I), Asphalt | AC14: =IF(AB14="","N/A",VLOOKUP(AB14,CHOOSE({1,2},Table2[Pay Item Description],Table2[Units]),2,0)) -> L.F. | AD14: ='Maintenance Policies'!D15*($C$5*9) -> 19500.097 | AE14: =IF(AB14="","N/A",VLOOKUP(AB14,CHOOSE({1,2},Table2[Pay Item Description],Table2[Unit Cost]),2,0)) -> 4 | AF14: =AE14*AD14 -> 78000.39 | AH14: 2 | AI14: =IF(AJ14="",0,VLOOKUP(AJ14,CHOOSE({1,2},Table2[Pay Item Description],Table2[Pay Item No.]),2,0)) -> P-101-5.2a | AJ14: =Pay_Items!D6 -> Crack Repair (Type I), Asphalt | AK14: =IF(AJ14="","N/A",VLOOKUP(AJ14,CHOOSE({1,2},Table2[Pay Item Description],Table2[Units]),2,0)) -> L.F. | AL14: ='Maintenance Policies'!D19*($C$5*9) -> 21000.105 | AM14: =IF(AJ14="","N/A",VLOOKUP(AJ14,CHOOSE({1,2},Table2[Pay Item Description],Table2[Unit Cost]),2,0)) -> 4 | AN14: =AM14*AL14 -> 84000.42 | AP14: 2 | AQ14: =IF(AR14="",0,VLOOKUP(AR14,CHOOSE({1,2},Table2[Pay Item Description],Table2[Pay Item No.]),2,0)) -> P-603-5.1 | AR14: =Pay_Items!D54 -> Emulsified Asphalt Tack Coat | AS14: =IF(AR14="","N/A",VLOOKUP(AR14,CHOOSE({1,2},Table2[Pay Item Description],Table2[Units]),2,0)) -> GAL | AT14: ='Maintenance Policies'!D22*$C$5*AQ9 -> 6666.7 | AU14: =IF(AR14="","N/A",VLOOKUP(AR14,CHOOSE({1,2},Table2[Pay Item Description],Table2[Unit Cost]),2,0)) -> 4.5 | AV14: =AU14*AT14 -> 30000.15 | AX14: 2 | AY14: =IF(AZ14="",0,VLOOKUP(AZ14,CHOOSE({1,2},Table2[Pay Item Description],Table2[Pay Item No.]),2,0)) -> P-101-5.3 | AZ14: =Pay_Items!D10 -> Markings Removal | BA14: =IF(AZ14="","N/A",VLOOKUP(AZ14,CHOOSE({1,2},Table2[Pay Item Description],Table2[Units]),2,0)) -> S.F. | BB14: ='Maintenance Policies'!D26*$C$8 -> 15000 | BC14: =IF(AZ14="","N/A",VLOOKUP(AZ14,CHOOSE({1,2},Table2[Pay Item Description],Table2[Unit Cost]),2,0)) -> 0.77777778 | BD14: =BC14*BB14 -> 11666.667 | BF14: 2 | BG14: =IF(BH14="",0,VLOOKUP(BH14,CHOOSE({1,2},Table2[Pay Item Description],Table2[Pay Item No.]),2,0)) -> P-101-5.2a | BH14: =Pay_Items!D6 -> Crack Repair (Type I), Asphalt | BI14: =IF(BH14="","N/A",VLOOKUP(BH14,CHOOSE({1,2},Table2[Pay Item Description],Table2[Units]),2,0)) -> L.F. | BJ14: ='Maintenance Policies'!D29*($C$5*9) -> 24000.12 | BK14: =IF(BH14="","N/A",VLOOKUP(BH14,CHOOSE({1,2},Table2[Pay Item Description],Table2[Unit Cost]),2,0)) -> 4 | BL14: =BK14*BJ14 -> 96000.48
A15: 3 | B15: =IF(C15="",0,VLOOKUP(C15,CHOOSE({1,2},Table2[Pay Item Description],Table2[Pay Item No.]),2,0)) -> 0 | D15: =IF(C15="","N/A",VLOOKUP(C15,CHOOSE({1,2},Table2[Pay Item Description],Table2[Units]),2,0)) -> N/A | F15: =IF(C15="","N/A",VLOOKUP(C15,CHOOSE({1,2},Table2[Pay Item Description],Table2[Unit Cost]),2,0)) -> N/A | G15: =IF(B15<>0,F15*E15,0) -> 0 | J15: 3 | K15: =IF(L15="",0,VLOOKUP(L15,CHOOSE({1,2},Table2[Pay Item Description],Table2[Pay Item No.]),2,0)) -> P-620-5.1a | L15: =Pay_Items!D56 -> Markings (prep, markings, reflective media) | M15: =IF(L15="","N/A",VLOOKUP(L15,CHOOSE({1,2},Table2[Pay Item Description],Table2[Units]),2,0)) -> S.F. | N15: ='Maintenance Policies'!D11*$C$8 -> 15000 | O15: =IF(L15="","N/A",VLOOKUP(L15,CHOOSE({1,2},Table2[Pay Item Description],Table2[Unit Cost]),2,0)) -> 0.66666667 | P15: =O15*N15 -> 10000 | R15: 3 | S15: =IF(T15="",0,VLOOKUP(T15,CHOOSE({1,2},Table2[Pay Item Description],Table2[Pay Item No.]),2,0)) -> P-620-5.1a | T15: =Pay_Items!D56 -> Markings (prep, markings, reflective media) | U15: =Pay_Items!E56 -> S.F. | V15: ='Maintenance Policies'!D13*$C$8 -> 15000 | W15: =IF(T15="","N/A",VLOOKUP(T15,CHOOSE({1,2},Table2[Pay Item Description],Table2[Unit Cost]),2,0)) -> 0.66666667 | X15: =W15*V15 -> 10000 | Z15: 3 | AA15: =IF(AB15="",0,VLOOKUP(AB15,CHOOSE({1,2},Table2[Pay Item Description],Table2[Pay Item No.]),2,0)) -> P-608-8.1 | AB15: =C7 -> Emulsified Asphalt Surface Treatment | AC15: =IF(AB15="","N/A",VLOOKUP(AB15,CHOOSE({1,2},Table2[Pay Item Description],Table2[Units]),2,0)) -> S.Y. | AD15: ='Maintenance Policies'!D16*$C$5 -> 66667 | AE15: =IF(AB15="","N/A",VLOOKUP(AB15,CHOOSE({1,2},Table2[Pay Item Description],Table2[Unit Cost]),2,0)) -> 4 | AF15: =AE15*AD15 -> 266668 | AH15: 3 | AI15: =IF(AJ15="",0,VLOOKUP(AJ15,CHOOSE({1,2},Table2[Pay Item Description],Table2[Pay Item No.]),2,0)) -> P-608-8.1 | AJ15: =C7 -> Emulsified Asphalt Surface Treatment | AK15: =IF(AJ15="","N/A",VLOOKUP(AJ15,CHOOSE({1,2},Table2[Pay Item Description],Table2[Units]),2,0)) -> S.Y. | AL15: ='Maintenance Policies'!D20*$C$5 -> 66667 | AM15: =IF(AJ15="","N/A",VLOOKUP(AJ15,CHOOSE({1,2},Table2[Pay Item Description],Table2[Unit Cost]),2,0)) -> 4 | AN15: =AM15*AL15 -> 266668 | AP15: 3 | AQ15: =IF(AR15="",0,VLOOKUP(AR15,CHOOSE({1,2},Table2[Pay Item Description],Table2[Pay Item No.]),2,0)) -> P-401-8.1a | AR15: =Pay_Items!D37 -> Asphalt Surface Course | AS15: =IF(AR15="","N/A",VLOOKUP(AR15,CHOOSE({1,2},Table2[Pay Item Description],Table2[Units]),2,0)) -> TON | AT15: ='Maintenance Policies'!D22*$C$5*AQ6*AQ7/2000 -> 8000.04 | AU15: =IF(AR15="","N/A",VLOOKUP(AR15,CHOOSE({1,2},Table2[Pay Item Description],Table2[Unit Cost]),2,0)) -> 130 | AV15: =AU15*AT15 -> 1040005.2 | AX15: 3 | AY15: =IF(AZ15="",0,VLOOKUP(AZ15,CHOOSE({1,2},Table2[Pay Item Description],Table2[Pay Item No.]),2,0)) -> P-620-5.1a | AZ15: =Pay_Items!D56 -> Markings (prep, markings, reflective media) | BA15: =IF(AZ15="","N/A",VLOOKUP(AZ15,CHOOSE({1,2},Table2[Pay Item Description],Table2[Units]),2,0)) -> S.F. | BB15: ='Maintenance Policies'!D27*$C$8 -> 15000 | BC15: =IF(AZ15="","N/A",VLOOKUP(AZ15,CHOOSE({1,2},Table2[Pay Item Description],Table2[Unit Cost]),2,0)) -> 0.66666667 | BD15: =BC15*BB15 -> 10000 | BF15: 3 | BG15: =IF(BH15="",0,VLOOKUP(BH15,CHOOSE({1,2},Table2[Pay Item Description],Table2[Pay Item No.]),2,0)) -> P-608-8.1 | BH15: =C7 -> Emulsified Asphalt Surface Treatment | BI15: =IF(BH15="","N/A",VLOOKUP(BH15,CHOOSE({1,2},Table2[Pay Item Description],Table2[Units]),2,0)) -> S.Y. | BJ15: ='Maintenance Policies'!D30*$C$5 -> 66667 | BK15: =IF(BH15="","N/A",VLOOKUP(BH15,CHOOSE({1,2},Table2[Pay Item Description],Table2[Unit Cost]),2,0)) -> 4 | BL15: =BK15*BJ15 -> 266668
A16: 4 | B16: =IF(C16="",0,VLOOKUP(C16,CHOOSE({1,2},Table2[Pay Item Description],Table2[Pay Item No.]),2,0)) -> 0 | D16: =IF(C16="","N/A",VLOOKUP(C16,CHOOSE({1,2},Table2[Pay Item Description],Table2[Units]),2,0)) -> N/A | F16: =IF(C16="","N/A",VLOOKUP(C16,CHOOSE({1,2},Table2[Pay Item Description],Table2[Unit Cost]),2,0)) -> N/A | G16: =IF(B16<>0,F16*E16,0) -> 0 | O16: Subtotal | P16: =SUM(P13:P15) -> 288334.67 | W16: Subtotal | X16: =SUM(X13:X15) -> 288334.67 | Z16: 4 | AA16: =IF(AB16="",0,VLOOKUP(AB16,CHOOSE({1,2},Table2[Pay Item Description],Table2[Pay Item No.]),2,0)) -> P-101-5.3 | AB16: =Pay_Items!D10 -> Markings Removal | AC16: =IF(AB16="","N/A",VLOOKUP(AB16,CHOOSE({1,2},Table2[Pay Item Description],Table2[Units]),2,0)) -> S.F. | AD16: ='Maintenance Policies'!D16*$C$8 -> 15000 | AE16: =IF(AB16="","N/A",VLOOKUP(AB16,CHOOSE({1,2},Table2[Pay Item Description],Table2[Unit Cost]),2,0)) -> 0.77777778 | AF16: =AE16*AD16 -> 11666.667 | AH16: 4 | AI16: =IF(AJ16="",0,VLOOKUP(AJ16,CHOOSE({1,2},Table2[Pay Item Description],Table2[Pay Item No.]),2,0)) -> P-101-5.3 | AJ16: =Pay_Items!D10 -> Markings Removal | AK16: =IF(AJ16="","N/A",VLOOKUP(AJ16,CHOOSE({1,2},Table2[Pay Item Description],Table2[Units]),2,0)) -> S.F. | AL16: ='Maintenance Policies'!D20*$C$8 -> 15000 | AM16: =IF(AJ16="","N/A",VLOOKUP(AJ16,CHOOSE({1,2},Table2[Pay Item Description],Table2[Unit Cost]),2,0)) -> 0.77777778 | AN16: =AM16*AL16 -> 11666.667 | AP16: 4 | AQ16: =IF(AR16="",0,VLOOKUP(AR16,CHOOSE({1,2},Table2[Pay Item Description],Table2[Pay Item No.]),2,0)) -> P-101-5.2a | AR16: =Pay_Items!D6 -> Crack Repair (Type I), Asphalt | AS16: =IF(AR16="","N/A",VLOOKUP(AR16,CHOOSE({1,2},Table2[Pay Item Description],Table2[Units]),2,0)) -> L.F. | AT16: ='Maintenance Policies'!D23*($C$5*9) -> 9000.045 | AU16: =IF(AR16="","N/A",VLOOKUP(AR16,CHOOSE({1,2},Table2[Pay Item Description],Table2[Unit Cost]),2,0)) -> 4 | AV16: =AU16*AT16 -> 36000.18 | BC16: Subtotal | BD16: =SUM(BD13:BD15) -> 288334.67 | BF16: 4 | BG16: =IF(BH16="",0,VLOOKUP(BH16,CHOOSE({1,2},Table2[Pay Item Description],Table2[Pay Item No.]),2,0)) -> P-101-5.3 | BH16: =Pay_Items!D10 -> Markings Removal | BI16: =IF(BH16="","N/A",VLOOKUP(BH16,CHOOSE({1,2},Table2[Pay Item Description],Table2[Units]),2,0)) -> S.F. | BJ16: =C8 -> 15000 | BK16: =IF(BH16="","N/A",VLOOKUP(BH16,CHOOSE({1,2},Table2[Pay Item Description],Table2[Unit Cost]),2,0)) -> 0.77777778 | BL16: =BK16*BJ16 -> 11666.667
A17: 5 | B17: =IF(C17="",0,VLOOKUP(C17,CHOOSE({1,2},Table2[Pay Item Description],Table2[Pay Item No.]),2,0)) -> 0 | D17: =IF(C17="","N/A",VLOOKUP(C17,CHOOSE({1,2},Table2[Pay Item Description],Table2[Units]),2,0)) -> N/A | F17: =IF(C17="","N/A",VLOOKUP(C17,CHOOSE({1,2},Table2[Pay Item Description],Table2[Unit Cost]),2,0)) -> N/A | G17: =IF(B17<>0,F17*E17,0) -> 0 | L17: Mobilization | P17: =('General Information'!$D$36/100)*P16 -> 28833.467 | T17: Mobilization | X17: =('General Information'!$D$36/100)*X16 -> 28833.467 | Z17: 5 | AA17: =IF(AB17="",0,VLOOKUP(AB17,CHOOSE({1,2},Table2[Pay Item Description],Table2[Pay Item No.]),2,0)) -> P-620-5.1a | AB17: =Pay_Items!D56 -> Markings (prep, markings, reflective media) | AC17: =IF(AB17="","N/A",VLOOKUP(AB17,CHOOSE({1,2},Table2[Pay Item Description],Table2[Units]),2,0)) -> S.F. | AD17: ='Maintenance Policies'!D17*$C$8 -> 15000 | AE17: =IF(AB17="","N/A",VLOOKUP(AB17,CHOOSE({1,2},Table2[Pay Item Description],Table2[Unit Cost]),2,0)) -> 0.66666667 | AF17: =AE17*AD17 -> 10000 | AH17: 5 | AI17: =IF(AJ17="",0,VLOOKUP(AJ17,CHOOSE({1,2},Table2[Pay Item Description],Table2[Pay Item No.]),2,0)) -> P-620-5.1a | AJ17: =Pay_Items!D56 -> Markings (prep, markings, reflective media) | AK17: =IF(AJ17="","N/A",VLOOKUP(AJ17,CHOOSE({1,2},Table2[Pay Item Description],Table2[Units]),2,0)) -> S.F. | AL17: ='Maintenance Policies'!D21*$C$8 -> 15000 | AM17: =IF(AJ17="","N/A",VLOOKUP(AJ17,CHOOSE({1,2},Table2[Pay Item Description],Table2[Unit Cost]),2,0)) -> 0.66666667 | AN17: =AM17*AL17 -> 10000 | AP17: 5 | AQ17: =IF(AR17="",0,VLOOKUP(AR17,CHOOSE({1,2},Table2[Pay Item Description],Table2[Pay Item No.]),2,0)) -> P-101-5.4a | AR17: =Pay_Items!D11 -> Spall Repair, Asphalt | AS17: =IF(AR17="","N/A",VLOOKUP(AR17,CHOOSE({1,2},Table2[Pay Item Description],Table2[Units]),2,0)) -> S.F. | AT17: ='Maintenance Policies'!D24*($C$5*9) -> 3000.015 | AU17: =IF(AR17="","N/A",VLOOKUP(AR17,CHOOSE({1,2},Table2[Pay Item Description],Table2[Unit Cost]),2,0)) -> 8.5 | AV17: =AU17*AT17 -> 25500.127 | AZ17: Mobilization | BD17: =('General Information'!$D$36/100)*BD16 -> 28833.467 | BF17: 5 | BG17: =IF(BH17="",0,VLOOKUP(BH17,CHOOSE({1,2},Table2[Pay Item Description],Table2[Pay Item No.]),2,0)) -> P-620-5.1a | BH17: =Pay_Items!D56 -> Markings (prep, markings, reflective media) | BI17: =IF(BH17="","N/A",VLOOKUP(BH17,CHOOSE({1,2},Table2[Pay Item Description],Table2[Units]),2,0)) -> S.F. | BJ17: ='Maintenance Policies'!D31*$C$8 -> 15000 | BK17: =IF(BH17="","N/A",VLOOKUP(BH17,CHOOSE({1,2},Table2[Pay Item Description],Table2[Unit Cost]),2,0)) -> 0.66666667 | BL17: =BK17*BJ17 -> 10000
A18: 6 | B18: =IF(C18="",0,VLOOKUP(C18,CHOOSE({1,2},Table2[Pay Item Description],Table2[Pay Item No.]),2,0)) -> 0 | D18: =IF(C18="","N/A",VLOOKUP(C18,CHOOSE({1,2},Table2[Pay Item Description],Table2[Units]),2,0)) -> N/A | F18: =IF(C18="","N/A",VLOOKUP(C18,CHOOSE({1,2},Table2[Pay Item Description],Table2[Unit Cost]),2,0)) -> N/A | G18: =IF(B18<>0,F18*E18,0) -> 0 | L18: Engineering | P18: =('General Information'!$D$37/100)*P16 -> 14416.733 | T18: Engineering | X18: =('General Information'!$D$37/100)*X16 -> 14416.733 | AE18: Subtotal | AF18: =SUM(AF13:AF17) -> 404585.25 | AM18: Subtotal | AN18: =SUM(AN13:AN17) -> 423335.34 | AP18: 6 | AQ18: =IF(AR18="",0,VLOOKUP(AR18,CHOOSE({1,2},Table2[Pay Item Description],Table2[Pay Item No.]),2,0)) -> P-620-5.1a | AR18: =Pay_Items!D56 -> Markings (prep, markings, reflective media) | AS18: =IF(AR18="","N/A",VLOOKUP(AR18,CHOOSE({1,2},Table2[Pay Item Description],Table2[Units]),2,0)) -> S.F. | AT18: ='Maintenance Policies'!D25*$C$8 -> 15000 | AU18: =IF(AR18="","N/A",VLOOKUP(AR18,CHOOSE({1,2},Table2[Pay Item Description],Table2[Unit Cost]),2,0)) -> 0.66666667 | AV18: =AU18*AT18 -> 10000 | AZ18: Engineering | BD18: =('General Information'!$D$37/100)*BD16 -> 14416.733 | BK18: Subtotal | BL18: =SUM(BL13:BL17) -> 448085.47
A19: 7 | B19: =IF(C19="",0,VLOOKUP(C19,CHOOSE({1,2},Table2[Pay Item Description],Table2[Pay Item No.]),2,0)) -> 0 | D19: =IF(C19="","N/A",VLOOKUP(C19,CHOOSE({1,2},Table2[Pay Item Description],Table2[Units]),2,0)) -> N/A | F19: =IF(C19="","N/A",VLOOKUP(C19,CHOOSE({1,2},Table2[Pay Item Description],Table2[Unit Cost]),2,0)) -> N/A | G19: =IF(B19<>0,F19*E19,0) -> 0 | O19: Total | P19: =SUM(P16:P18) -> 331584.87 | W19: Total | X19: =SUM(X16:X18) -> 331584.87 | AB19: Mobilization | AF19: =('General Information'!$D$36/100)*AF18 -> 40458.525 | AJ19: Mobilization | AN19: =('General Information'!$D$36/100)*AN18 -> 42333.534 | AU19: Subtotal | AV19: =SUM(AV13:AV18) -> 1474840.7 | BC19: Total | BD19: =SUM(BD16:BD18) -> 331584.87 | BH19: Mobilization | BL19: =('General Information'!$D$36/100)*BL18 -> 44808.547
A20: 8 | B20: =IF(C20="",0,VLOOKUP(C20,CHOOSE({1,2},Table2[Pay Item Description],Table2[Pay Item No.]),2,0)) -> 0 | D20: =IF(C20="","N/A",VLOOKUP(C20,CHOOSE({1,2},Table2[Pay Item Description],Table2[Units]),2,0)) -> N/A | F20: =IF(C20="","N/A",VLOOKUP(C20,CHOOSE({1,2},Table2[Pay Item Description],Table2[Unit Cost]),2,0)) -> N/A | G20: =IF(B20<>0,F20*E20,0) -> 0 | AB20: Engineering | AF20: =('General Information'!$D$37/100)*AF18 -> 20229.262 | AJ20: Engineering | AN20: =('General Information'!$D$37/100)*AN18 -> 21166.767 | AR20: Mobilization | AV20: =('General Information'!$D$36/100)*AV19 -> 147484.07 | BH20: Engineering | BL20: =('General Information'!$D$37/100)*BL18 -> 22404.273
A21: 9 | B21: =IF(C21="",0,VLOOKUP(C21,CHOOSE({1,2},Table2[Pay Item Description],Table2[Pay Item No.]),2,0)) -> 0 | D21: =IF(C21="","N/A",VLOOKUP(C21,CHOOSE({1,2},Table2[Pay Item Description],Table2[Units]),2,0)) -> N/A | F21: =IF(C21="","N/A",VLOOKUP(C21,CHOOSE({1,2},Table2[Pay Item Description],Table2[Unit Cost]),2,0)) -> N/A | G21: =IF(B21<>0,F21*E21,0) -> 0 | AE21: Total | AF21: =SUM(AF18:AF20) -> 465273.04 | AM21: Total | AN21: =SUM(AN18:AN20) -> 486835.64 | AR21: Engineering | AV21: =('General Information'!$D$37/100)*AV19 -> 73742.033 | BK21: Total | BL21: =SUM(BL18:BL20) -> 515298.29
A22: 10 | B22: =IF(C22="",0,VLOOKUP(C22,CHOOSE({1,2},Table2[Pay Item Description],Table2[Pay Item No.]),2,0)) -> 0 | D22: =IF(C22="","N/A",VLOOKUP(C22,CHOOSE({1,2},Table2[Pay Item Description],Table2[Units]),2,0)) -> N/A | F22: =IF(C22="","N/A",VLOOKUP(C22,CHOOSE({1,2},Table2[Pay Item Description],Table2[Unit Cost]),2,0)) -> N/A | G22: =IF(B22<>0,F22*E22,0) -> 0 | AU22: Total | AV22: =SUM(AV19:AV21) -> 1696066.8
A24: Subtotal | G24: =SUM(G13:G22) -> 0
B25: Mobilization | G25: =('General Information'!$D$36/100)*G24 -> 0
B26: Engineering | G26: =('General Information'!$D$37/100)*G24 -> 0
A27: Total | G27: =SUM(G24:G26) -> 0
A32: Net Present Worth
A33: HMA Reconstruction - Alternative 1 | I33: Hidden
B35: Item | C35: Year Applied | D35: Actual Cost | E35: Discounted Cost
B36: Initial Construction | C36: =C6 -> 2028 | D36: =G27 -> 0 | E36: =D36 -> 0 | K36: Year | L36: Direct Cost | M36: Indirect Cost | N36: Total Discounted Cost
B37: Maintenance 1 | C37: ='Maintenance Policies'!E10 -> 4 | D37: =P19 -> 331584.87 | E37: =IF(C37>'General Information'!$D$33,0,D37/(1+('General Information'!$D$34/100))^C37) -> 294608.86 | K37: =C6 -> 2028 | L37: =IF(K37-$C$6>'General Information'!$D$33,0,IF(K37=$C$6,$D$36,0)+SUMIFS($D$37:$D$51,$C$37:$C$51,K37-$C$6,$B$37:$B$51,"<>*Indirect*")) -> 0 | M37: =IF(K37-$C$6>'General Information'!$D$33,0,SUMIFS($D$37:$D$51,$C$37:$C$51,K37-$C$6,$B$37:$B$51,"*Indirect*")) -> 0 | N37: =IF(K37-$C$6>'General Information'!$D$33,0,IF(K37=$C$6,$E$36,0)+SUMIF($C$37:$C$51,K37-$C$6,$E$37:$E$51)) -> 0
B38: Maintenance 1 Indirect Cost | C38: ='Maintenance Policies'!E10 -> 4 | D38: =F2*F4 -> 22675.73 | E38: =IF(C38>'General Information'!$D$33,0,D38/(1+('General Information'!$D$34/100))^C38) -> 20147.092 | K38: =K37+1 -> 2029 | L38: =IF(K38-$C$6>'General Information'!$D$33,0,IF(K38=$C$6,$D$36,0)+SUMIFS($D$37:$D$51,$C$37:$C$51,K38-$C$6,$B$37:$B$51,"<>*Indirect*")) -> 0 | M38: =IF(K38-$C$6>'General Information'!$D$33,0,SUMIFS($D$37:$D$51,$C$37:$C$51,K38-$C$6,$B$37:$B$51,"*Indirect*")) -> 0 | N38: =IF(K38-$C$6>'General Information'!$D$33,0,IF(K38=$C$6,$E$36,0)+SUMIF($C$37:$C$51,K38-$C$6,$E$37:$E$51)) -> 0
B39: Maintenance 2 | C39: ='Maintenance Policies'!E12 -> 8 | D39: =X19 -> 331584.87 | E39: =IF(C39>'General Information'!$D$33,0,D39/(1+('General Information'!$D$34/100))^C39) -> 261756.16 | K39: =K38+1 -> 2030 | L39: =IF(K39-$C$6>'General Information'!$D$33,0,IF(K39=$C$6,$D$36,0)+SUMIFS($D$37:$D$51,$C$37:$C$51,K39-$C$6,$B$37:$B$51,"<>*Indirect*")) -> 0 | M39: =IF(K39-$C$6>'General Information'!$D$33,0,SUMIFS($D$37:$D$51,$C$37:$C$51,K39-$C$6,$B$37:$B$51,"*Indirect*")) -> 0 | N39: =IF(K39-$C$6>'General Information'!$D$33,0,IF(K39=$C$6,$E$36,0)+SUMIF($C$37:$C$51,K39-$C$6,$E$37:$E$51)) -> 0
B40: Maintenance 2 Indirect Cost | C40: ='Maintenance Policies'!E12 -> 8 | D40: =F2*F5 -> 22675.73 | E40: =IF(C40>'General Information'!$D$33,0,D40/(1+('General Information'!$D$34/100))^C40) -> 17900.431 | K40: =K39+1 -> 2031 | L40: =IF(K40-$C$6>'General Information'!$D$33,0,IF(K40=$C$6,$D$36,0)+SUMIFS($D$37:$D$51,$C$37:$C$51,K40-$C$6,$B$37:$B$51,"<>*Indirect*")) -> 0 | M40: =IF(K40-$C$6>'General Information'!$D$33,0,SUMIFS($D$37:$D$51,$C$37:$C$51,K40-$C$6,$B$37:$B$51,"*Indirect*")) -> 0 | N40: =IF(K40-$C$6>'General Information'!$D$33,0,IF(K40=$C$6,$E$36,0)+SUMIF($C$37:$C$51,K40-$C$6,$E$37:$E$51)) -> 0
B41: Maintenance 3 | C41: ='Maintenance Policies'!E14 -> 12 | D41: =AF21 -> 465273.04 | E41: =IF(C41>'General Information'!$D$33,0,D41/(1+('General Information'!$D$34/100))^C41) -> 326333.15 | K41: =K40+1 -> 2032 | L41: =IF(K41-$C$6>'General Information'!$D$33,0,IF(K41=$C$6,$D$36,0)+SUMIFS($D$37:$D$51,$C$37:$C$51,K41-$C$6,$B$37:$B$51,"<>*Indirect*")) -> 331584.87 | M41: =IF(K41-$C$6>'General Information'!$D$33,0,SUMIFS($D$37:$D$51,$C$37:$C$51,K41-$C$6,$B$37:$B$51,"*Indirect*")) -> 22675.73 | N41: =IF(K41-$C$6>'General Information'!$D$33,0,IF(K41=$C$6,$E$36,0)+SUMIF($C$37:$C$51,K41-$C$6,$E$37:$E$51)) -> 314755.95
B42: Maintenance 3 Indirect Cost | C42: ='Maintenance Policies'!E14 -> 12 | D42: =F2*F6 -> 29154.51 | E42: =IF(C42>'General Information'!$D$33,0,D42/(1+('General Information'!$D$34/100))^C42) -> 20448.387 | K42: =K41+1 -> 2033 | L42: =IF(K42-$C$6>'General Information'!$D$33,0,IF(K42=$C$6,$D$36,0)+SUMIFS($D$37:$D$51,$C$37:$C$51,K42-$C$6,$B$37:$B$51,"<>*Indirect*")) -> 0 | M42: =IF(K42-$C$6>'General Information'!$D$33,0,SUMIFS($D$37:$D$51,$C$37:$C$51,K42-$C$6,$B$37:$B$51,"*Indirect*")) -> 0 | N42: =IF(K42-$C$6>'General Information'!$D$33,0,IF(K42=$C$6,$E$36,0)+SUMIF($C$37:$C$51,K42-$C$6,$E$37:$E$51)) -> 0
B43: Maintenance 4 | C43: ='Maintenance Policies'!E18 -> 16 | D43: =AN21 -> 486835.64 | E43: =IF(C43>'General Information'!$D$33,0,D43/(1+('General Information'!$D$34/100))^C43) -> 303379.88 | K43: =K42+1 -> 2034 | L43: =IF(K43-$C$6>'General Information'!$D$33,0,IF(K43=$C$6,$D$36,0)+SUMIFS($D$37:$D$51,$C$37:$C$51,K43-$C$6,$B$37:$B$51,"<>*Indirect*")) -> 0 | M43: =IF(K43-$C$6>'General Information'!$D$33,0,SUMIFS($D$37:$D$51,$C$37:$C$51,K43-$C$6,$B$37:$B$51,"*Indirect*")) -> 0 | N43: =IF(K43-$C$6>'General Information'!$D$33,0,IF(K43=$C$6,$E$36,0)+SUMIF($C$37:$C$51,K43-$C$6,$E$37:$E$51)) -> 0
B44: Maintenance 4 Indirect Cost | C44: ='Maintenance Policies'!E18 -> 16 | D44: =F2*F7 -> 29154.51 | E44: =IF(C44>'General Information'!$D$33,0,D44/(1+('General Information'!$D$34/100))^C44) -> 18168.127 | K44: =K43+1 -> 2035 | L44: =IF(K44-$C$6>'General Information'!$D$33,0,IF(K44=$C$6,$D$36,0)+SUMIFS($D$37:$D$51,$C$37:$C$51,K44-$C$6,$B$37:$B$51,"<>*Indirect*")) -> 0 | M44: =IF(K44-$C$6>'General Information'!$D$33,0,SUMIFS($D$37:$D$51,$C$37:$C$51,K44-$C$6,$B$37:$B$51,"*Indirect*")) -> 0 | N44: =IF(K44-$C$6>'General Information'!$D$33,0,IF(K44=$C$6,$E$36,0)+SUMIF($C$37:$C$51,K44-$C$6,$E$37:$E$51)) -> 0
