Workbook

Sheet TMP(NewPCC)_IndirectCost
A1: =HYPERLINK("#'General Information'!D9","◄ General Information") -> ◄ General Information | C1: =HYPERLINK("#Summary!G1","Summary") -> Summary | D1: =$A$34 -> PCC Reconstruction - Alternative 2 | I1: Hidden
A2: Initial Construction Costs: | E2: Average Daily Revenue: | F2: =IF('General Information'!$D$38="Yes",SUMIF(RevenueData!$A:$A,'General Information'!$D$10,RevenueData!$B:$B)+SUMIF(RevenueData!$A:$A,'General Information'!$D$10,RevenueData!$C:$C)+SUMIF(RevenueData!$A:$A,'General Information'!$D$10,RevenueData!$D:$D)+SUMIF(RevenueData!$A:$A,'General Information'!$D$10,RevenueData!$E:$E)+SUMIF(RevenueData!$A:$A,'General Information'!$D$10,RevenueData!$F:$F)+SUMIF(RevenueData!$A:$A,'General Information'!$D$10,RevenueData!$G:$G)+SUMIF(RevenueData!$A:$A,'General Information'!$D$10,RevenueData!$H:$H),0) -> 5441.17 | G2: =IF(AND('General Information'!$D$38="Yes",F2=0),"No revenue data for this airport - lost revenue set to $0. Contact Aeronautics.","") | J2: Maintenance 1 | R2: Rehabilitation 1
A3: STEP 4 of 5 · The quantities for this alternative. Grey cells are yours: C4 to C7 project data (filled from General Information), F4 and F5 closure days, C13 to C22 pay items and E13 to E22 quantities. Everything else calculates. Unit costs come from Pay_Items, and C11 picks which division they are priced from.
A4: Pavement Type: | C4: New PCC | E4: Maintenance 1 Duration (Days) | F4: =ROUNDUP(C5*550/(50*100/9)/10000,0)+ROUNDUP(C5*'Maintenance Policies'!D38/10000,0)+ROUNDUP(C5*'Maintenance Policies'!D39/5000,0)+ROUNDUP(C5*'Maintenance Policies'!D40/5000,0) -> 8
A5: Mainline Pavement Area: | C5: ='General Information'!D26 -> 45883 | D5: S.Y. | E5: Rehabilitation 1 Duration (Days) | F5: =ROUNDUP(C5*550/(50*100/9)/10000,0)+ROUNDUP(C5*'Maintenance Policies'!D44/10000,0)+ROUNDUP(C5*'Maintenance Policies'!D43/5000,0)+ROUNDUP(C5*'Maintenance Policies'!D42/5000,0)+ROUNDUP(C5*'Maintenance Policies'!D41/1000,0)+7 -> 16
A6: Initial Construction Year: | C6: ='General Information'!D25 -> 2028
A7: Markings Area: | C7: ='General Information'!D28 -> 12000 | D7: S.F. | J7: No. of Slabs: | K7: =C5/((12.5*12.5)/9) -> 2642.8608
J8: Joint length: | K8: =K7*25+((K7/8)*12.5) -> 70200.99
I10: Price column: 1 Regular, 2 Middle, 3 West, 4 East
B11: Price from: | C11: Regular | D11: =IF(OR($C$11="Regular",$C$11=""),"Regular is the statewide Unit Cost column on Pay_Items.","Prices from the "&$C$11&" column on Pay_Items: "&SUM($I$13:$I$22)&" of "&COUNT($I$13:$I$22)&" pay items used here have a "&$C$11&" cost, the rest fall back to Unit Cost.") -> Regular is the statewide Unit Cost column on Pay_Items. | I11: =IFERROR(MATCH($C$11,PriceSources,0),1) -> 1
A12: Item No. | B12: Pay Item | C12: Description | D12: Unit | E12: Qty | F12: Unit Cost | G12: Item Cost | J12: Item No. | K12: Pay Item | L12: Description | M12: Unit | N12: Qty | O12: Unit Cost | P12: Item Cost | R12: Item No. | S12: Pay Item | T12: Description | U12: Unit | V12: Qty | W12: Unit Cost | X12: Item Cost
A13: 1 | B13: =IF(C13="","",VLOOKUP(C13,CHOOSE({1,2},Table2[Pay Item Description],Table2[Pay Item No.]),2,0)) | D13: =IF(C13="","N/A",VLOOKUP(C13,CHOOSE({1,2},Table2[Pay Item Description],Table2[Units]),2,0)) -> N/A | F13: =IF(C13="","N/A",IF(INDEX(UnitCostGrid,MATCH(C13,PayItemKeys,0),$I$11)="",INDEX(UnitCostGrid,MATCH(C13,PayItemKeys,0),1),INDEX(UnitCostGrid,MATCH(C13,PayItemKeys,0),$I$11))) -> N/A | G13: =IF(C13="",0,F13*E13) -> 0 | I13: =IF(C13="","",IF(INDEX(UnitCostGrid,MATCH(C13,PayItemKeys,0),$I$11)="",0,1)) | J13: 1 | K13: =IF(L13="",0,VLOOKUP(L13,CHOOSE({1,2},Table2[Pay Item Description],Table2[Pay Item No.]),2,0)) -> P-605-5.1a | L13: =Pay_Items!D55 -> Joint Clean and Reseal, Concrete | M13: =IF(L13="","N/A",VLOOKUP(L13,CHOOSE({1,2},Table2[Pay Item Description],Table2[Units]),2,0)) -> L.F. | N13: =K8*'Maintenance Policies'!D37 -> 70200.99 | O13: =IF(L13="","N/A",IF(INDEX(UnitCostGrid,MATCH(L13,PayItemKeys,0),$I$11)="",INDEX(UnitCostGrid,MATCH(L13,PayItemKeys,0),1),INDEX(UnitCostGrid,MATCH(L13,PayItemKeys,0),$I$11))) -> 7 | P13: =O13*N13 -> 491406.93 | R13: 1 | S13: =IF(T13="",0,VLOOKUP(T13,CHOOSE({1,2},Table2[Pay Item Description],Table2[Pay Item No.]),2,0)) -> P-101-5.5c | T13: =Pay_Items!D15 -> Slab Replacement, Concrete | U13: =IF(T13="","N/A",VLOOKUP(T13,CHOOSE({1,2},Table2[Pay Item Description],Table2[Units]),2,0)) -> S.Y. | V13: ='Maintenance Policies'!D41*C5 -> 917.66 | W13: =IF(T13="","N/A",IF(INDEX(UnitCostGrid,MATCH(T13,PayItemKeys,0),$I$11)="",INDEX(UnitCostGrid,MATCH(T13,PayItemKeys,0),1),INDEX(UnitCostGrid,MATCH(T13,PayItemKeys,0),$I$11))) -> 100 | X13: =W13*V13 -> 91766
A14: 2 | B14: =IF(C14="","",VLOOKUP(C14,CHOOSE({1,2},Table2[Pay Item Description],Table2[Pay Item No.]),2,0)) | D14: =IF(C14="","N/A",VLOOKUP(C14,CHOOSE({1,2},Table2[Pay Item Description],Table2[Units]),2,0)) -> N/A | F14: =IF(C14="","N/A",IF(INDEX(UnitCostGrid,MATCH(C14,PayItemKeys,0),$I$11)="",INDEX(UnitCostGrid,MATCH(C14,PayItemKeys,0),1),INDEX(UnitCostGrid,MATCH(C14,PayItemKeys,0),$I$11))) -> N/A | G14: =IF(C14="",0,F14*E14) -> 0 | I14: =IF(C14="","",IF(INDEX(UnitCostGrid,MATCH(C14,PayItemKeys,0),$I$11)="",0,1)) | J14: 2 | K14: =VLOOKUP(L14,CHOOSE({1,2},Table2[Pay Item Description],Table2[Pay Item No.]),2,0) -> P-101-5.2c | L14: =Pay_Items!D8 -> Crack Seal, Concrete | M14: =IF(L14="","N/A",VLOOKUP(L14,CHOOSE({1,2},Table2[Pay Item Description],Table2[Units]),2,0)) -> L.F. | N14: ='Maintenance Policies'!D38*(C5*9) -> 1032.3675 | O14: =IF(L14="","N/A",IF(INDEX(UnitCostGrid,MATCH(L14,PayItemKeys,0),$I$11)="",INDEX(UnitCostGrid,MATCH(L14,PayItemKeys,0),1),INDEX(UnitCostGrid,MATCH(L14,PayItemKeys,0),$I$11))) -> 8 | P14: =O14*N14 -> 8258.94 | R14: 2 | S14: =VLOOKUP(T14,CHOOSE({1,2},Table2[Pay Item Description],Table2[Pay Item No.]),2,0) -> P-101-5.5b | T14: =Pay_Items!D14 -> Full-Depth Repair, Concrete | U14: =IF(T14="","N/A",VLOOKUP(T14,CHOOSE({1,2},Table2[Pay Item Description],Table2[Units]),2,0)) -> S.Y. | V14: ='Maintenance Policies'!D42*C5 -> 137.649 | W14: =IF(T14="","N/A",IF(INDEX(UnitCostGrid,MATCH(T14,PayItemKeys,0),$I$11)="",INDEX(UnitCostGrid,MATCH(T14,PayItemKeys,0),1),INDEX(UnitCostGrid,MATCH(T14,PayItemKeys,0),$I$11))) -> 120 | X14: =W14*V14 -> 16517.88
A15: 3 | B15: =IF(C15="","",VLOOKUP(C15,CHOOSE({1,2},Table2[Pay Item Description],Table2[Pay Item No.]),2,0)) | D15: =IF(C15="","N/A",VLOOKUP(C15,CHOOSE({1,2},Table2[Pay Item Description],Table2[Units]),2,0)) -> N/A | F15: =IF(C15="","N/A",IF(INDEX(UnitCostGrid,MATCH(C15,PayItemKeys,0),$I$11)="",INDEX(UnitCostGrid,MATCH(C15,PayItemKeys,0),1),INDEX(UnitCostGrid,MATCH(C15,PayItemKeys,0),$I$11))) -> N/A | G15: =IF(C15="",0,F15*E15) -> 0 | I15: =IF(C15="","",IF(INDEX(UnitCostGrid,MATCH(C15,PayItemKeys,0),$I$11)="",0,1)) | J15: 3 | K15: =VLOOKUP(L15,CHOOSE({1,2},Table2[Pay Item Description],Table2[Pay Item No.]),2,0) -> P-101-5.5a | L15: =Pay_Items!D13 -> Spall Repair, Concrete | M15: =IF(L15="","N/A",VLOOKUP(L15,CHOOSE({1,2},Table2[Pay Item Description],Table2[Units]),2,0)) -> S.F. | N15: ='Maintenance Policies'!D39*(C5*9) -> 536.8311 | O15: =IF(L15="","N/A",IF(INDEX(UnitCostGrid,MATCH(L15,PayItemKeys,0),$I$11)="",INDEX(UnitCostGrid,MATCH(L15,PayItemKeys,0),1),INDEX(UnitCostGrid,MATCH(L15,PayItemKeys,0),$I$11))) -> 60 | P15: =O15*N15 -> 32209.866 | R15: 3 | S15: =VLOOKUP(T15,CHOOSE({1,2},Table2[Pay Item Description],Table2[Pay Item No.]),2,0) -> P-101-5.5a | T15: =Pay_Items!D13 -> Spall Repair, Concrete | U15: =IF(T15="","N/A",VLOOKUP(T15,CHOOSE({1,2},Table2[Pay Item Description],Table2[Units]),2,0)) -> S.F. | V15: ='Maintenance Policies'!D43*(C5*9) -> 536.8311 | W15: =IF(T15="","N/A",IF(INDEX(UnitCostGrid,MATCH(T15,PayItemKeys,0),$I$11)="",INDEX(UnitCostGrid,MATCH(T15,PayItemKeys,0),1),INDEX(UnitCostGrid,MATCH(T15,PayItemKeys,0),$I$11))) -> 60 | X15: =W15*V15 -> 32209.866
A16: 4 | B16: =IF(C16="","",VLOOKUP(C16,CHOOSE({1,2},Table2[Pay Item Description],Table2[Pay Item No.]),2,0)) | D16: =IF(C16="","N/A",VLOOKUP(C16,CHOOSE({1,2},Table2[Pay Item Description],Table2[Units]),2,0)) -> N/A | F16: =IF(C16="","N/A",IF(INDEX(UnitCostGrid,MATCH(C16,PayItemKeys,0),$I$11)="",INDEX(UnitCostGrid,MATCH(C16,PayItemKeys,0),1),INDEX(UnitCostGrid,MATCH(C16,PayItemKeys,0),$I$11))) -> N/A | G16: =IF(C16="",0,F16*E16) -> 0 | I16: =IF(C16="","",IF(INDEX(UnitCostGrid,MATCH(C16,PayItemKeys,0),$I$11)="",0,1)) | J16: 4 | K16: =VLOOKUP(L16,CHOOSE({1,2},Table2[Pay Item Description],Table2[Pay Item No.]),2,0) -> P-101-5.5b | L16: =Pay_Items!D14 -> Full-Depth Repair, Concrete | M16: =IF(L16="","N/A",VLOOKUP(L16,CHOOSE({1,2},Table2[Pay Item Description],Table2[Units]),2,0)) -> S.Y. | N16: ='Maintenance Policies'!D40*C5 -> 137.649 | O16: =IF(L16="","N/A",IF(INDEX(UnitCostGrid,MATCH(L16,PayItemKeys,0),$I$11)="",INDEX(UnitCostGrid,MATCH(L16,PayItemKeys,0),1),INDEX(UnitCostGrid,MATCH(L16,PayItemKeys,0),$I$11))) -> 120 | P16: =O16*N16 -> 16517.88 | R16: 4 | S16: =VLOOKUP(T16,CHOOSE({1,2},Table2[Pay Item Description],Table2[Pay Item No.]),2,0) -> P-101-5.2c | T16: =Pay_Items!D8 -> Crack Seal, Concrete | U16: =IF(T16="","N/A",VLOOKUP(T16,CHOOSE({1,2},Table2[Pay Item Description],Table2[Units]),2,0)) -> L.F. | V16: ='Maintenance Policies'!D44*(C5*9) -> 1238.841 | W16: =IF(T16="","N/A",IF(INDEX(UnitCostGrid,MATCH(T16,PayItemKeys,0),$I$11)="",INDEX(UnitCostGrid,MATCH(T16,PayItemKeys,0),1),INDEX(UnitCostGrid,MATCH(T16,PayItemKeys,0),$I$11))) -> 8 | X16: =W16*V16 -> 9910.728
A17: 5 | B17: =IF(C17="","",VLOOKUP(C17,CHOOSE({1,2},Table2[Pay Item Description],Table2[Pay Item No.]),2,0)) | D17: =IF(C17="","N/A",VLOOKUP(C17,CHOOSE({1,2},Table2[Pay Item Description],Table2[Units]),2,0)) -> N/A | F17: =IF(C17="","N/A",IF(INDEX(UnitCostGrid,MATCH(C17,PayItemKeys,0),$I$11)="",INDEX(UnitCostGrid,MATCH(C17,PayItemKeys,0),1),INDEX(UnitCostGrid,MATCH(C17,PayItemKeys,0),$I$11))) -> N/A | G17: =IF(C17="",0,F17*E17) -> 0 | I17: =IF(C17="","",IF(INDEX(UnitCostGrid,MATCH(C17,PayItemKeys,0),$I$11)="",0,1)) | O17: Subtotal | P17: =SUM(P13:P16) -> 548393.62 | R17: 5 | S17: =VLOOKUP(T17,CHOOSE({1,2},Table2[Pay Item Description],Table2[Pay Item No.]),2,0) -> P-605-5.1a | T17: =Pay_Items!D55 -> Joint Clean and Reseal, Concrete | U17: =IF(T17="","N/A",VLOOKUP(T17,CHOOSE({1,2},Table2[Pay Item Description],Table2[Units]),2,0)) -> L.F. | V17: ='Maintenance Policies'!D45*K8 -> 70200.99 | W17: =IF(T17="","N/A",IF(INDEX(UnitCostGrid,MATCH(T17,PayItemKeys,0),$I$11)="",INDEX(UnitCostGrid,MATCH(T17,PayItemKeys,0),1),INDEX(UnitCostGrid,MATCH(T17,PayItemKeys,0),$I$11))) -> 7 | X17: =W17*V17 -> 491406.93
A18: 6 | B18: =IF(C18="","",VLOOKUP(C18,CHOOSE({1,2},Table2[Pay Item Description],Table2[Pay Item No.]),2,0)) | D18: =IF(C18="","N/A",VLOOKUP(C18,CHOOSE({1,2},Table2[Pay Item Description],Table2[Units]),2,0)) -> N/A | F18: =IF(C18="","N/A",IF(INDEX(UnitCostGrid,MATCH(C18,PayItemKeys,0),$I$11)="",INDEX(UnitCostGrid,MATCH(C18,PayItemKeys,0),1),INDEX(UnitCostGrid,MATCH(C18,PayItemKeys,0),$I$11))) -> N/A | G18: =IF(C18="",0,F18*E18) -> 0 | I18: =IF(C18="","",IF(INDEX(UnitCostGrid,MATCH(C18,PayItemKeys,0),$I$11)="",0,1)) | L18: Mobilization | P18: =('General Information'!$D$36/100)*P17 -> 54839.362 | W18: Subtotal | X18: =SUM(X13:X17) -> 641811.4
A19: 7 | B19: =IF(C19="","",VLOOKUP(C19,CHOOSE({1,2},Table2[Pay Item Description],Table2[Pay Item No.]),2,0)) | D19: =IF(C19="","N/A",VLOOKUP(C19,CHOOSE({1,2},Table2[Pay Item Description],Table2[Units]),2,0)) -> N/A | F19: =IF(C19="","N/A",IF(INDEX(UnitCostGrid,MATCH(C19,PayItemKeys,0),$I$11)="",INDEX(UnitCostGrid,MATCH(C19,PayItemKeys,0),1),INDEX(UnitCostGrid,MATCH(C19,PayItemKeys,0),$I$11))) -> N/A | G19: =IF(C19="",0,F19*E19) -> 0 | I19: =IF(C19="","",IF(INDEX(UnitCostGrid,MATCH(C19,PayItemKeys,0),$I$11)="",0,1)) | L19: Engineering | P19: =('General Information'!$D$37/100)*P17 -> 27419.681 | T19: Mobilization | X19: =('General Information'!$D$36/100)*X18 -> 64181.14
A20: 8 | B20: =IF(C20="","",VLOOKUP(C20,CHOOSE({1,2},Table2[Pay Item Description],Table2[Pay Item No.]),2,0)) | D20: =IF(C20="","N/A",VLOOKUP(C20,CHOOSE({1,2},Table2[Pay Item Description],Table2[Units]),2,0)) -> N/A | F20: =IF(C20="","N/A",IF(INDEX(UnitCostGrid,MATCH(C20,PayItemKeys,0),$I$11)="",INDEX(UnitCostGrid,MATCH(C20,PayItemKeys,0),1),INDEX(UnitCostGrid,MATCH(C20,PayItemKeys,0),$I$11))) -> N/A | G20: =IF(C20="",0,F20*E20) -> 0 | I20: =IF(C20="","",IF(INDEX(UnitCostGrid,MATCH(C20,PayItemKeys,0),$I$11)="",0,1)) | O20: Total | P20: =SUM(P17:P19) -> 630652.66 | T20: Engineering | X20: =('General Information'!$D$37/100)*X18 -> 32090.57
A21: 9 | B21: =IF(C21="","",VLOOKUP(C21,CHOOSE({1,2},Table2[Pay Item Description],Table2[Pay Item No.]),2,0)) | D21: =IF(C21="","N/A",VLOOKUP(C21,CHOOSE({1,2},Table2[Pay Item Description],Table2[Units]),2,0)) -> N/A | F21: =IF(C21="","N/A",IF(INDEX(UnitCostGrid,MATCH(C21,PayItemKeys,0),$I$11)="",INDEX(UnitCostGrid,MATCH(C21,PayItemKeys,0),1),INDEX(UnitCostGrid,MATCH(C21,PayItemKeys,0),$I$11))) -> N/A | G21: =IF(C21="",0,F21*E21) -> 0 | I21: =IF(C21="","",IF(INDEX(UnitCostGrid,MATCH(C21,PayItemKeys,0),$I$11)="",0,1)) | W21: Total | X21: =SUM(X18:X20) -> 738083.11
A22: 10 | B22: =IF(C22="","",VLOOKUP(C22,CHOOSE({1,2},Table2[Pay Item Description],Table2[Pay Item No.]),2,0)) | D22: =IF(C22="","N/A",VLOOKUP(C22,CHOOSE({1,2},Table2[Pay Item Description],Table2[Units]),2,0)) -> N/A | F22: =IF(C22="","N/A",IF(INDEX(UnitCostGrid,MATCH(C22,PayItemKeys,0),$I$11)="",INDEX(UnitCostGrid,MATCH(C22,PayItemKeys,0),1),INDEX(UnitCostGrid,MATCH(C22,PayItemKeys,0),$I$11))) -> N/A | G22: =IF(C22="",0,F22*E22) -> 0 | I22: =IF(C22="","",IF(INDEX(UnitCostGrid,MATCH(C22,PayItemKeys,0),$I$11)="",0,1))
A24: Subtotal | G24: =SUM(G13:G22) -> 0
B25: Mobilization | G25: =('General Information'!$D$36/100)*G24 -> 0
B26: Engineering | G26: =('General Information'!$D$37/100)*G24 -> 0
A27: Total | G27: =SUM(G24:G26) -> 0
A33: Net Present Worth
A34: PCC Reconstruction - Alternative 2 | I34: Hidden
B36: Item | C36: Year Applied | D36: Actual Cost | E36: Discounted Cost
B37: Initial Construction | C37: =C6 -> 2028 | D37: =G27 -> 0 | E37: =D37 -> 0 | K37: Year | L37: Direct Cost | M37: Indirect Cost | N37: Total Discounted Cost
B38: Maintenance 1 | C38: ='Maintenance Policies'!E37 -> 19 | D38: =P20 -> 630652.66 | E38: =IF(C38>'General Information'!$D$33,0,D38/(1+('General Information'!$D$34/100))^C38) -> 359652.4 | K38: =C6 -> 2028 | L38: =IF(K38-$C$6>'General Information'!$D$33,0,IF(K38=$C$6,$D$37,0)+SUMIFS($D$38:$D$42,$C$38:$C$42,K38-$C$6,$B$38:$B$42,"<>*Indirect*")) -> 0 | M38: =IF(K38-$C$6>'General Information'!$D$33,0,SUMIFS($D$38:$D$42,$C$38:$C$42,K38-$C$6,$B$38:$B$42,"*Indirect*")) -> 0 | N38: =IF(K38-$C$6>'General Information'!$D$33,0,IF(K38=$C$6,$E$37,0)+SUMIF($C$38:$C$42,K38-$C$6,$E$38:$E$42)) -> 0
B39: Maintenance 1 Indirect Cost | C39: ='Maintenance Policies'!E37 -> 19 | D39: =F2*F4 -> 43529.36 | E39: =IF(C39>'General Information'!$D$33,0,D39/(1+('General Information'!$D$34/100))^C39) -> 24824.186 | K39: =K38+1 -> 2029 | L39: =IF(K39-$C$6>'General Information'!$D$33,0,IF(K39=$C$6,$D$37,0)+SUMIFS($D$38:$D$42,$C$38:$C$42,K39-$C$6,$B$38:$B$42,"<>*Indirect*")) -> 0 | M39: =IF(K39-$C$6>'General Information'!$D$33,0,SUMIFS($D$38:$D$42,$C$38:$C$42,K39-$C$6,$B$38:$B$42,"*Indirect*")) -> 0 | N39: =IF(K39-$C$6>'General Information'!$D$33,0,IF(K39=$C$6,$E$37,0)+SUMIF($C$38:$C$42,K39-$C$6,$E$38:$E$42)) -> 0
B40: Rehabilitation 1 | C40: ='Maintenance Policies'!E41 -> 27 | D40: =X21 -> 738083.11 | E40: =IF(C40>'General Information'!$D$33,0,D40/(1+('General Information'!$D$34/100))^C40) -> 332276.94 | K40: =K39+1 -> 2030 | L40: =IF(K40-$C$6>'General Information'!$D$33,0,IF(K40=$C$6,$D$37,0)+SUMIFS($D$38:$D$42,$C$38:$C$42,K40-$C$6,$B$38:$B$42,"<>*Indirect*")) -> 0 | M40: =IF(K40-$C$6>'General Information'!$D$33,0,SUMIFS($D$38:$D$42,$C$38:$C$42,K40-$C$6,$B$38:$B$42,"*Indirect*")) -> 0 | N40: =IF(K40-$C$6>'General Information'!$D$33,0,IF(K40=$C$6,$E$37,0)+SUMIF($C$38:$C$42,K40-$C$6,$E$38:$E$42)) -> 0
B41: Rehabilitation 1 Indirect Cost | C41: ='Maintenance Policies'!E41 -> 27 | D41: =F2*F5 -> 87058.72 | E41: =IF(C41>'General Information'!$D$33,0,D41/(1+('General Information'!$D$34/100))^C41) -> 39192.883 | K41: =K40+1 -> 2031 | L41: =IF(K41-$C$6>'General Information'!$D$33,0,IF(K41=$C$6,$D$37,0)+SUMIFS($D$38:$D$42,$C$38:$C$42,K41-$C$6,$B$38:$B$42,"<>*Indirect*")) -> 0 | M41: =IF(K41-$C$6>'General Information'!$D$33,0,SUMIFS($D$38:$D$42,$C$38:$C$42,K41-$C$6,$B$38:$B$42,"*Indirect*")) -> 0 | N41: =IF(K41-$C$6>'General Information'!$D$33,0,IF(K41=$C$6,$E$37,0)+SUMIF($C$38:$C$42,K41-$C$6,$E$38:$E$42)) -> 0
B42: Salvage | C42: ='General Information'!D33 -> 30 | D42: =-'Maintenance Policies'!D46*G27 -> 0 | E42: =IF(C42>'General Information'!$D$33,0,D42/(1+('General Information'!$D$34/100))^C42) -> 0 | K42: =K41+1 -> 2032 | L42: =IF(K42-$C$6>'General Information'!$D$33,0,IF(K42=$C$6,$D$37,0)+SUMIFS($D$38:$D$42,$C$38:$C$42,K42-$C$6,$B$38:$B$42,"<>*Indirect*")) -> 0 | M42: =IF(K42-$C$6>'General Information'!$D$33,0,SUMIFS($D$38:$D$42,$C$38:$C$42,K42-$C$6,$B$38:$B$42,"*Indirect*")) -> 0 | N42: =IF(K42-$C$6>'General Information'!$D$33,0,IF(K42=$C$6,$E$37,0)+SUMIF($C$38:$C$42,K42-$C$6,$E$38:$E$42)) -> 0
B43: Net Present Worth | E43: =SUM(E37:E42) -> 755946.41 | K43: =K42+1 -> 2033 | L43: =IF(K43-$C$6>'General Information'!$D$33,0,IF(K43=$C$6,$D$37,0)+SUMIFS($D$38:$D$42,$C$38:$C$42,K43-$C$6,$B$38:$B$42,"<>*Indirect*")) -> 0 | M43: =IF(K43-$C$6>'General Information'!$D$33,0,SUMIFS($D$38:$D$42,$C$38:$C$42,K43-$C$6,$B$38:$B$42,"*Indirect*")) -> 0 | N43: =IF(K43-$C$6>'General Information'!$D$33,0,IF(K43=$C$6,$E$37,0)+SUMIF($C$38:$C$42,K43-$C$6,$E$38:$E$42)) -> 0
K44: =K43+1 -> 2034 | L44: =IF(K44-$C$6>'General Information'!$D$33,0,IF(K44=$C$6,$D$37,0)+SUMIFS($D$38:$D$42,$C$38:$C$42,K44-$C$6,$B$38:$B$42,"<>*Indirect*")) -> 0 | M44: =IF(K44-$C$6>'General Information'!$D$33,0,SUMIFS($D$38:$D$42,$C$38:$C$42,K44-$C$6,$B$38:$B$42,"*Indirect*")) -> 0 | N44: =IF(K44-$C$6>'General Information'!$D$33,0,IF(K44=$C$6,$E$37,0)+SUMIF($C$38:$C$42,K44-$C$6,$E$38:$E$42)) -> 0
K45: =K44+1 -> 2035 | L45: =IF(K45-$C$6>'General Information'!$D$33,0,IF(K45=$C$6,$D$37,0)+SUMIFS($D$38:$D$42,$C$38:$C$42,K45-$C$6,$B$38:$B$42,"<>*Indirect*")) -> 0 | M45: =IF(K45-$C$6>'General Information'!$D$33,0,SUMIFS($D$38:$D$42,$C$38:$C$42,K45-$C$6,$B$38:$B$42,"*Indirect*")) -> 0 | N45: =IF(K45-$C$6>'General Information'!$D$33,0,IF(K45=$C$6,$E$37,0)+SUMIF($C$38:$C$42,K45-$C$6,$E$38:$E$42)) -> 0
K46: =K45+1 -> 2036 | L46: =IF(K46-$C$6>'General Information'!$D$33,0,IF(K46=$C$6,$D$37,0)+SUMIFS($D$38:$D$42,$C$38:$C$42,K46-$C$6,$B$38:$B$42,"<>*Indirect*")) -> 0 | M46: =IF(K46-$C$6>'General Information'!$D$33,0,SUMIFS($D$38:$D$42,$C$38:$C$42,K46-$C$6,$B$38:$B$42,"*Indirect*")) -> 0 | N46: =IF(K46-$C$6>'General Information'!$D$33,0,IF(K46=$C$6,$E$37,0)+SUMIF($C$38:$C$42,K46-$C$6,$E$38:$E$42)) -> 0
K47: =K46+1 -> 2037 | L47: =IF(K47-$C$6>'General Information'!$D$33,0,IF(K47=$C$6,$D$37,0)+SUMIFS($D$38:$D$42,$C$38:$C$42,K47-$C$6,$B$38:$B$42,"<>*Indirect*")) -> 0 | M47: =IF(K47-$C$6>'General Information'!$D$33,0,SUMIFS($D$38:$D$42,$C$38:$C$42,K47-$C$6,$B$38:$B$42,"*Indirect*")) -> 0 | N47: =IF(K47-$C$6>'General Information'!$D$33,0,IF(K47=$C$6,$E$37,0)+SUMIF($C$38:$C$42,K47-$C$6,$E$38:$E$42)) -> 0
K48: =K47+1 -> 2038 | L48: =IF(K48-$C$6>'General Information'!$D$33,0,IF(K48=$C$6,$D$37,0)+SUMIFS($D$38:$D$42,$C$38:$C$42,K48-$C$6,$B$38:$B$42,"<>*Indirect*")) -> 0 | M48: =IF(K48-$C$6>'General Information'!$D$33,0,SUMIFS($D$38:$D$42,$C$38:$C$42,K48-$C$6,$B$38:$B$42,"*Indirect*")) -> 0 | N48: =IF(K48-$C$6>'General Information'!$D$33,0,IF(K48=$C$6,$E$37,0)+SUMIF($C$38:$C$42,K48-$C$6,$E$38:$E$42)) -> 0
...

Sheet Overview
B1: =HYPERLINK("#'General Information'!D9","◄ General Information") -> ◄ General Information | E1: =HYPERLINK("#Summary!G1","Summary") -> Summary | G1: Overview
B2: STEP 1 of 5 · What the framework does and the rules behind it. Read this and Instructions, then go to General Information.
B4: A life-cycle cost analysis compares alternatives over their whole life, not their first bill.
B5: You describe two or more ways to build the same runway. The workbook prices each one from the TDOT pay-item list, adds the maintenance and rehabilitation each will need over the analysis period, discounts it all to today’s money, and reports which costs least in present worth.
B8: What you provide | F8: What the workbook adds | J8: What you get
B9: • The airport and the runway | F9: • Unit costs by division | J9: • Net present worth per option
B10: • Pavement areas and markings | F10: • Maintenance and rehabilitation timing | J10: • Equivalent annual cost
B11: • Two or more alternatives | F11: • Salvage on remaining life | J11: • Sensitivity to the discount rate
B12: • Quantities per pay item | F12: • Lost revenue during closures | J12: • Eight charts and a comparison
B14: THE RULES BEHIND IT
B15: =IF('General Information'!$D$33="","30",'General Information'!$D$33)&" years" -> 30 years | E15: =IF('General Information'!$D$34="","3",'General Information'!$D$34)&"%" -> 3% | H15: =IF('General Information'!$D$36="","10",'General Information'!$D$36)&" / "&IF('General Information'!$D$37="","5",'General Information'!$D$37)&"%" -> 10 / 5% | K15: Remaining life
B16: analysis period, live from General Information D33 | E16: discount rate, D34; FAA follows OMB Circular A-94 | H16: mobilization and engineering, D36 and D37 | K16: salvage basis: remaining life over expected life (AAPTP, FAA)
B18: HOW A STUDY RUNS
B19: =HYPERLINK("#Instructions!B1","1 Overview & Instructions") -> 1 Overview & Instructions | E19: =HYPERLINK("#'General Information'!D9","2 General Information") -> 2 General Information | G19: =HYPERLINK("#Pay_Items!A1","3 Pay Items") -> 3 Pay Items | I19: =HYPERLINK("#'General Information'!D9","4 Alternatives") -> 4 Alternatives | K19: =HYPERLINK("#Summary!G1","5 Summary") -> 5 Summary
B21: TDOT Aeronautics Division | H21: Before you start
B22: 7335 Centennial Boulevard | H22: Enable macros and ActiveX when Excel asks. The Alternative Setup form and the pay-item pickers need them. If the yellow bar does not appear, check Trust Center › ActiveX Settings and restart Excel.
B23: Nashville, Tennessee 37209
B24: 615-741-3208
B25: tn.gov/tdot/aeronautics.html
B27: BACKGROUND

Sheet Instructions
B1: =HYPERLINK("#'General Information'!D9","◄ General Information") -> ◄ General Information | E1: =HYPERLINK("#Summary!G1","Summary") -> Summary | G1: Instructions
B2: STEP 1 of 5 · How to run an analysis, start to finish. When you are ready, go to General Information and fill in the grey cells.
B4: First, enable content.
B5: Macros and ActiveX must be on, or the Alternative Setup form and the pay-item pickers will not run. Trust Center › ActiveX Settings, then restart Excel.
B7: Set the study up | H7: Run it
B8: 1 | C8: Fill in General Information | H8: 4 | I8: Add each alternative
C9: Pick the airport from the dropdown and the ID, city, county and region fill themselves. Then the runway areas and the LCCA parameters, D9 to D39. The amber banner lists whatever is still missing. | I9: Back on General Information, click Alternative Setup. Name it, choose the pavement type, and the form builds a worksheet for it. Enter quantities against the pay items there.
B12: 2 | C12: Check the unit costs on Pay_Items | H12: 5 | I12: Read the Summary
C13: Every alternative is priced from that sheet, and the grey Unit Cost column is the one to edit. An item that ships with no cost prices at zero. | I13: It updates by itself. The banner names the lowest present worth; the two key plots show why it wins and whether it still wins at other discount rates.
B16: 3 | C16: Review the maintenance policies | H16: 6 | I16: Start the next study
C17: Four tables set what each pavement type gets done to it and in which year. They are live: a rate or a year changed there moves every alternative of that type. | I17: The + New Study button saves a cleared copy wherever you choose, with every input blank and every alternative removed. The study you have open is untouched.
B21: Grey means yours | F21: Where to look things up | J21: If a number looks wrong
B22: A grey cell is one you type in. | F22: Typical Values: the usual ranges, with sources. | J22: Check the Unit Cost column first, then the year a policy is applied.
B23: Everything else calculates: leave it alone. | F23: Method: every formula as it stands in the sheet. | J23: Both feed every alternative of that pavement type at once.
B26: THE ORIGINAL STEP-BY-STEP NOTES

Sheet General Information
C1: General Information | D1: STEP 2 of 5 · fill in the grey cells, D9 to D39.
B2: Saves a fresh copy for the next study. This file stays as is. | F2: HOW TO USE THIS WORKBOOK
F3: 1. Overview and Instructions: what the framework does and the rules behind it. 2. General Information (this sheet): fill in the grey cells, D9 to D39. 3. Pay_Items: check the unit costs your alternatives will be priced from. 4. Alternative Setup: add each alternative, then enter its quantities on the sheet it creates. 5. Summary: read the comparison. It updates by itself. Grey cells are yours; white cells calculate. Typical Values has the usual ranges, Method every formula.
B4: 1 Overview › 2 General Information › 3 Pay Items › 4 Alternatives › 5 Summary
K7: Hidden
B8: Airport information | L8: Name | M8: ID | N8: City | O8: County | P8: Region | Q8: Owner | S8: Branch Use
C9: Airport Name: | D9: Gatlinburg-Pigeon Forge Airport | F9: =IF(LEN(IF(D9="","Airport Name, ","")&IF(D25="","Construction Year, ","")&IF(D26="","Mainline Area, ","")&IF(D28="","Markings Area, ","")&IF(D33="","Analysis Period, ","")&IF(D34="","Discount Rate, ",""))=0,"All required inputs are filled. Next: click Alternative Setup.","Still needed: "&LEFT(IF(D9="","Airport Name, ","")&IF(D25="","Construction Year, ","")&IF(D26="","Mainline Area, ","")&IF(D28="","Markings Area, ","")&IF(D33="","Analysis Period, ","")&IF(D34="","Discount Rate, ",""),LEN(IF(D9="","Airport Name, ","")&IF(D25="","Construction Year, ","")&IF(D26="","Mainline Area, ","")&IF(D28="","Markings Area, ","")&IF(D33="","Analysis Period, ","")&IF(D34="","Discount Rate, ",""))-2)) -> All required inputs are filled. Next: click Alternative Setup. | N9: N/A | O9: N/A
C10: Airport ID: | D10: =IF(D9="","N/A",VLOOKUP(Airport_Name,Table17[],2)) -> GKT | L10: Abernathy Field | M10: GZS | N10: Pulaski | O10: Giles | P10: Middle | S10: Runway
C11: City: | D11: =IF(D9="","N/A",VLOOKUP(Airport_Name,Table17[],3)) -> Sevierville | L11: Arnold Field | M11: M31 | N11: Halls | O11: Lauderdale | P11: West | S11: Taxiway
C12: County: | D12: =IF(D9="","N/A",VLOOKUP(Airport_Name,Table17[],4)) -> Sevier | L12: Beech River Regional Airport | M12: PVE | N12: Lexington/Parsons | O12: Henderson | P12: West | S12: Apron
C13: State Region: | D13: =IF(D9="","N/A",VLOOKUP(Airport_Name,Table17[],5)) -> East | L13: Benton County Airport | M13: 0M4 | N13: Camden | O13: Benton | P13: West
C14: Design Consultant: | D14: ARA | L14: Bomar Field-Shelbyville Municipal Airport | M14: SYI | N14: Shelbyville | O14: Bedford | P14: Middle
C15: Project Number: | D15: 6101 | L15: Carroll County Airport | M15: HZD | N15: Huntingdon | O15: Carroll | P15: West | S15: Markings Type
C16: Project Name: | D16: Runway 10-28 Reconstruction | L16: Centerville Municipal Airport | M16: GHM | N16: Centerville | O16: Hickman | P16: Middle
C17: Date of LCCA: | L17: Charles W. Baker Field | M17: 2M8 | N17: Millington | O17: Shelby | P17: West | S17: Reflective
L18: Chilhowee Gliderport | M18: 92A | N18: Benton | O18: Polk | P18: East | S18: Non-Reflective
L19: Cleveland Regional Jetport | M19: RZR | N19: Cleveland | O19: Bradley | P19: East
B20: Project and pavement | L20: Collegedale Municipal Airport | M20: FGU | N20: Collegedale | O20: Hamilton | P20: East
C21: Branch Type: | D21: Runway | L21: Colonel Tommy C. Stiner-Campbell County Airport | M21: JAU | N21: Jacksboro | O21: Campbell | P21: East | S21: Weight Category
C22: Branch Name: | D22: Runway 10-28 | L22: Covington Municipal Airport | M22: M04 | N22: Covington | O22: Tipton | P22: West
C23: Project Type: | D23: Reconstruction | L23: Crossville Memorial Airport/Whitson Field | M23: CSV | N23: Crossville | O23: Cumberland | P23: East | S23: < 60,000 lbs
C24: Project Description: | D24: Full-depth reconstruction, 5,506 x 75 ft, no paved shoulders | L24: Dallas Bay Skypark Airport | M24: 1A0 | N24: Chattanooga | O24: Hamilton | P24: East | S24: > 60,000 to < 100,000 lbs
C25: Initial Construction Year: | D25: 2028 | F25: Construction year; the analysis period starts here. | L25: Dickson Municipal Airport | M25: M02 | N25: Dickson | O25: Dickson | P25: Middle | S25: > 100,000 lbs
C26: Mainline Area, S.Y.: | D26: 45883 | F26: Length x width / 9. TN GA: 4,000-6,000 ft x 75-100 ft wide. | L26: Dyersburg Municipal Airport | M26: DYR | N26: Dyersburg | O26: Dyer | P26: West
C27: Shoulder Area, S.Y.: | D27: 0 | F27: Paved shoulders only; usually 0 at TN GA airports. | L27: Elizabethton Municipal Airport | M27: 0A9 | N27: Elizabethton | O27: Carter | P27: East
C28: Markings, S.F.: | D28: 12000 | F28: About 2,000-3,000 SF per 1,000 ft of runway. | L28: Ellington Airport | M28: LUG | N28: Lewisburg | O28: Marshall | P28: Middle
C29: Markings, Type: | D29: Reflective | L29: Everett-Stewart Airport | M29: UCY | N29: Union City | O29: Obion | P29: West
L30: Fayette County Airport | M30: FYE | N30: Somerville | O30: Fayette | P30: West
L31: Fayetteville Municipal Airport | M31: FYM | N31: Fayetteville | O31: Lincoln | P31: Middle
B32: LCCA parameters | L32: Franklin County Airport | M32: UOS | N32: Sewanee | O32: Franklin | P32: Middle
C33: Analysis Period, years: | D33: 30 | F33: TDOT policy 30 years; FAA leaves the period to the engineer. | L33: Gatlinburg-Pigeon Forge Airport | M33: GKT | N33: Sevierville | O33: Sevier | P33: East
C34: Discount Rate, percent: | D34: 3 | F34: TDOT 3%. FAA uses the OMB A-94 real rate, 2.0% in 2026. | L34: General Dewitt Spain Airport | M34: M01 | N34: Memphis | O34: Shelby | P34: West
C35: Salvage Value, $: | F35: Remaining service life at the end of the analysis period; computed on Maintenance Policies. | L35: Gibson County Airport | M35: TGC | N35: Trenton | O35: Gibson | P35: West
C36: Mobilization, percent: | D36: 10 | F36: Percent of pay items; workbook default 10. | L36: Greeneville-Green County Municipal Airport | M36: GCY | N36: Greeneville | O36: Greene | P36: East
C37: Engineering, percent: | D37: 5 | F37: Percent of pay items; now applied to initial construction too. | L37: Hassell-Carroll Field | M37: M29 | N37: Clifton | O37: Wayne | P37: Middle
C38: Account Indirect Cost (Yes/No) | D38: Yes | F38: Yes counts lost revenue during closures (17 airports have data). | L38: Hawkins County Airport | M38: RVN | N38: Rogersville | O38: Hawkins | P38: East
C39: Airport Daily Revenue | D39: =IF(D38<>"Yes","",IF(COUNTIF(RevenueData!$A:$A,$D$10)=0,"Missing Airport Revenue",SUMIF(RevenueData!$A:$A,$D$10,RevenueData!$B:$B)+SUMIF(RevenueData!$A:$A,$D$10,RevenueData!$C:$C)+SUMIF(RevenueData!$A:$A,$D$10,RevenueData!$D:$D)+SUMIF(RevenueData!$A:$A,$D$10,RevenueData!$E:$E)+SUMIF(RevenueData!$A:$A,$D$10,RevenueData!$F:$F)+SUMIF(RevenueData!$A:$A,$D$10,RevenueData!$G:$G)+SUMIF(RevenueData!$A:$A,$D$10,RevenueData!$H:$H))) -> 5441.17 | L39: Henry County Airport | M39: PHT | N39: Paris | O39: Henry | P39: West
L40: Houston County Airport | M40: M93 | N40: McKinnon | O40: Houston | P40: Middle
B41: Alternative Setup | L41: Humboldt Municipal Airport | M41: M53 | N41: Humboldt | O41: Gibson | P41: West
L42: Humphreys County Airport | M42: 0M5 | N42: Waverly | O42: Humphreys | P42: Middle
...

Sheet Pay_Items
A1: =HYPERLINK("#'General Information'!D9","◄ General Information") -> ◄ General Information | B1: =HYPERLINK("#Summary!G1","Summary") -> Summary | C1: Pay Items | D1: =IF(COUNTBLANK($F$4:$F$59)=0,"Every pay item carries a unit cost.",COUNTBLANK($F$4:$F$59)&" of "&COUNTA($D$4:$D$59)&" pay items carry no unit cost, flagged amber below.") -> 28 of 56 pay items carry no unit cost, flagged amber below. | F1: STEP 3 of 5 | G1: Average Pay Item Unit Cost
A2: Division | B2: Division Type | C2: Pay Item No. | D2: Pay Item Description | E2: Units | F2: Unit Cost | G2: Middle | H2: West | I2: East | J2: Notes
B3: Default | E3: N/A | F3: N/A
A4: Part 3 – Sitework | B4: Sitework | C4: P-101-5.1a | D4: Pavement Removal, Asphalt | E4: S.Y. | F4: 4.2 | J4: Thickness adjustment or multiple
B5: Sitework | C5: P-101-5.1b | D5: Pavement Removal, Concrete | E5: S.Y. | J5: Thickness adjustment or multiple
B6: Sitework | C6: P-101-5.2a | D6: Crack Repair (Type I), Asphalt | E6: L.F. | F6: 4
B7: Sitework | C7: P-101-5.2b | D7: Crack Repair (Type II), Asphalt | E7: L.F. | F7: 6.5
B8: Sitework | C8: P-101-5.2c | D8: Crack Seal, Concrete | E8: L.F. | F8: 8
B9: Sitework | C9: P-101-5.2d | D9: Crack Repair, Concrete | E9: L.F. | F9: 8.5
B10: Sitework | C10: P-101-5.3 | D10: Markings Removal | E10: S.F. | F10: =7/9 -> 0.77777778
B11: Sitework | C11: P-101-5.4a | D11: Spall Repair, Asphalt | E11: S.F. | F11: 8.5 | J11: Thickness adjustment or multiple
B12: Sitework | C12: P-101-5.4b | D12: Full-Depth Repair, Asphalt | E12: S.F. | J12: Assumed Section: 4-inch HMA; 4-inch P-209
B13: Sitework | C13: P-101-5.5a | D13: Spall Repair, Concrete | E13: S.F. | F13: 60 | J13: Thickness adjustment or multiple
B14: Sitework | C14: P-101-5.5b | D14: Full-Depth Repair, Concrete | E14: S.Y. | F14: 120 | J14: Thickness adjustment or multiple
B15: Sitework | C15: P-101-5.5c | D15: Slab Replacement, Concrete | E15: S.Y. | F15: 100
B16: Sitework | C16: P-101-5.6 | D16: Cold Milling | E16: S.Y. | F16: =10/2 -> 5 | J16: Thickness adjustment or multiple
B17: Sitework | C17: P-152-4.1 | D17: Unclassified Excavation | E17: C.Y. | F17: 12
B18: Sitework | C18: P-152-4.2 | D18: Embankment In-Place | E18: C.Y.
B19: Sitework | C19: P-154-5.1 | D19: Subbase Course | E19: C.Y. | F19: 55
B20: Sitework | C20: P-154-5.2 | D20: Separation Geotextile (P-154) | E20: S.Y.
B21: Sitework | C21: P-155-8.1 | D21: Lime Treated subgrade | E21: S.Y. | F21: 10 | J21: Thickness adjustment or multiple
B22: Sitework | C22: P-156-8.1 | D22: Cement-Treated Subgrade | E22: S.Y. | J22: Thickness adjustment or multiple
B23: Sitework | C23: P-157-8.1a | D23: Cement Kiln Dust-Treated Subgrade | E23: S.Y. | J23: Thickness adjustment or multiple
B24: Sitework | C24: P-157-8.1b | D24: Lime Kiln Dust-Treated Subgrade | E24: S.Y. | J24: Thickness adjustment or multiple
B25: Sitework | C25: P-158-8.1 | D25: Fly Ash-Treated Subgrade | E25: S.Y. | J25: Thickness adjustment or multiple
A26: Part 4 – Base Courses | B26: Base Course | C26: P-207-5.1 | D26: In-Place Full Depth Reclamation (FDR) Recycled Asphalt Aggregate Base Course | E26: S.Y. | J26: Thickness adjustment or multiple
B27: Base Course | C27: P-208-5.1 | D27: Aggregate Base Course | E27: C.Y.
B28: Base Course | C28: P-208-5.2 | D28: Separation Geotextile (P-208) | E28: S.Y.
B29: Base Course | C29: P-209-5.1 | D29: Crushed Aggregate Base Course | E29: C.Y. | F29: 65
B30: Base Course | C30: P-209-5.2 | D30: Separation Geotextile (P-209) | E30: S.Y.
B31: Base Course | C31: P-219-5.1 | D31: Recycled Concrete Aggregate Base Course | E31: C.Y.
B32: Base Course | C32: P-219-5.2 | D32: Separation Geotextile (P-219) | E32: S.Y.
B33: Base Course | C33: P-220-6.1 | D33: Cement-Treated Soil Base Course | E33: S.Y. | J33: Thickness adjustment or multiple
A34: Part 5 – Stabilized Base Courses | B34: Stabilized Base Course | C34: P-304-8.1 | D34: Cement-Treated Base Course | E34: C.Y. | J34: If S.Y., then thickness adjustment
B35: Stabilized Base Course | C35: P-306-8.1 | D35: Lean Concrete Base Course | E35: C.Y. | J35: If S.Y., then thickness adjustment
B36: Stabilized Base Course | C36: P-307-7.1 | D36: Cement-Treated Permeable Base Course (CTPB) | E36: C.Y. | J36: If S.Y., then thickness adjustment
A37: Part 6 – Flexible Pavements | B37: Flexible Pavement | C37: P-401-8.1a | D37: Asphalt Surface Course | E37: TON | F37: 130
B38: Flexible Pavement | C38: P-401-8.1b | D38: Asphalt Base Course | E38: TON | F38: 120
B39: Flexible Pavement | C39: P-401-8.1c | D39: Asphalt Leveling Course | E39: TON | F39: 110
B40: Flexible Pavement | C40: P-403-8.1a | D40: Asphalt Mixture Surface Course | E40: TON
...

Sheet Database
A1: Alternative List
A3: Name | B3: Type | C3: Description | D3: Alt Worksheet Name
A4: Alternative 1 | B4: HMA-New | C4: New HMA | D4: Alt 1 (New HMA)
A5: Alternative 2 | B5: PCC-New | C5: New PCC | D5: Alt 2 (New PCC)
A6: Alternative 3 | B6: PCC-New | C6: New PCC | D6: Alt 3 (New PCC)

Sheet Maintenance Policies
B1: =HYPERLINK("#'General Information'!D9","◄ General Information") -> ◄ General Information | C1: =HYPERLINK("#Summary!G1","Summary") -> Summary
B2: Maintenance & Rehabilitation Policies
B3: This sheet is live. Every alternative reads its Rate and Year Applied straight from these four tables, so a year moved here moves that event on every alternative of that type and every number on the Summary. The grey cells are the ones to edit.
B4: Rate is the share of the quantity the activity covers: 1 is the whole mainline area, the whole markings area or the whole joint length. Year Applied counts years after construction, and an event past the analysis period drops to zero.
B5: Table 1 drives a New HMA alternative, Table 2 a New PCC alternative, Table 3 an HMA overlay and Table 4 a PCC rehabilitation.
B6: Rehabilitation | C6: Salvage credit | D6: No salvage | E6: Closure days come from Typical Values, not this sheet.
B8: Table 1. New HMA maintenance policies.
B9: Asphalt Maintenance | C9: Maintenance Item | D9: Rate | E9: Year Applied | F9: Asset life (yrs)
B10: Maintenance 1 | C10: Surface treatment, SYD | D10: 1 | E10: 4
C11: Paint markings, SFT | D11: 1
B12: Maintenance 2 | C12: Surface treatment, SYD | D12: 1 | E12: 8
C13: Paint markings, SFT | D13: 1
B14: Maintenance 3 | C14: Patching: 0.75% of area | D14: 0.0075 | E14: 12
C15: Crack sealing: 3.25% of area as linear feet | D15: 0.0325
C16: Surface treatment: 100% of area | D16: 1
C17: Paint markings: 100% of markings | D17: 1
B18: Maintenance 4 | C18: Patching: 1.00% of area | D18: 0.01 | E18: 16
C19: Crack sealing: 3.50% of area as linear feet | D19: 0.035
C20: Surface treatment: 100% of area | D20: 1
C21: Paint markings: 100% of markings | D21: 1
B22: Rehabilitation 1 | C22: Mill and overlay: 4-inch cold mill, tack coat, and asphalt overlay | D22: 1 | E22: 20
C23: Pre-overlay crack repair: 1.5% of area as linear feet | D23: 0.015
C24: Pre-overlay patching: 0.5% of area | D24: 0.005
C25: Paint markings: 100% of markings | D25: 1
B26: Maintenance 5 | C26: Surface treatment: 100% of area | D26: 1 | E26: 24
C27: Paint markings: 100% of markings | D27: 1
B28: Maintenance 6 | C28: Patching: 1.25% of area | D28: 0.0125 | E28: 28
C29: Crack sealing: 4.0% of area as linear feet | D29: 0.04
C30: Surface treatment: 100% of area | D30: 1
C31: Paint markings: 100% of markings | D31: 1
B32: Salvage | C32: ="Salvage value: "&TEXT(D32*F32,"0.#")&" of 16 years left on the mill and overlay"&" placed in year "&E22&" ("&TEXT(D32,"0.0%")&" of its cost) at the "&'General Information'!$D$33&"-year analysis period" -> Salvage value: 6 of 16 years left on the mill and overlay placed in year 20 (37.5% of its cost) at the 30-year analysis period | D32: =IF(E22>'General Information'!$D$33,0,MAX(0,MIN(1,(E22+F32-'General Information'!$D$33)/F32))) -> 0.375 | E32: ='General Information'!$D$33 -> 30 | F32: 16
B35: Table 2. New PCC maintenance policies.
B36: Concrete Maintenance | C36: Maintenance Item | D36: Rate | E36: Year Applied | F36: Asset life (yrs)
B37: Maintenance 1 | C37: Joint resealing: 100% of joints | D37: 1 | E37: 19
C38: Crack sealing: 0.25% of area as linear feet | D38: 0.0025
C39: Partial-depth patching: 0.13% of area | D39: 0.0013
C40: Full-depth patching: 0.30% of area | D40: 0.003
B41: Rehabilitation 1 | C41: Slab replacements: 2% of area | D41: 0.02 | E41: 27
C42: Full-depth patching: 0.30% of area | D42: 0.003
C43: Partial-depth patching: 0.13% of area | D43: 0.0013
...

Sheet TMP(NewHMA)_IndirectCost
A1: =HYPERLINK("#'General Information'!D9","◄ General Information") -> ◄ General Information | C1: =HYPERLINK("#Summary!G1","Summary") -> Summary | D1: =$A$33 -> HMA Reconstruction - Alternative 1 | I1: Hidden
A2: Initial Construction Costs: | E2: Average Daily Revenue: | F2: =IF('General Information'!$D$38="Yes",SUMIF(RevenueData!$A:$A,'General Information'!$D$10,RevenueData!$B:$B)+SUMIF(RevenueData!$A:$A,'General Information'!$D$10,RevenueData!$C:$C)+SUMIF(RevenueData!$A:$A,'General Information'!$D$10,RevenueData!$D:$D)+SUMIF(RevenueData!$A:$A,'General Information'!$D$10,RevenueData!$E:$E)+SUMIF(RevenueData!$A:$A,'General Information'!$D$10,RevenueData!$F:$F)+SUMIF(RevenueData!$A:$A,'General Information'!$D$10,RevenueData!$G:$G)+SUMIF(RevenueData!$A:$A,'General Information'!$D$10,RevenueData!$H:$H),0) -> 5441.17 | G2: =IF(AND('General Information'!$D$38="Yes",F2=0),"No revenue data for this airport - lost revenue set to $0. Contact Aeronautics.","") | J2: Maintenance 1 | R2: Maintenance 2 | Z2: Maintenance 3 | AH2: Maintenance 4 | AP2: Rehabilitation 1 | AX2: Maintenance 5 | BF2: Maintenance 6
A3: STEP 4 of 5 · The quantities for this alternative. Grey cells are yours: C4 to C8 project data (filled from General Information), F4 to F10 closure days, C13 to C22 pay items and E13 to E22 quantities. Everything else calculates. Unit costs come from Pay_Items, and C11 picks which division they are priced from.
A4: Pavement Type: | C4: New HMA | E4: Maintenance 1 Duration (Days) | F4: =ROUNDUP((C5/15000),0)+ROUNDUP((C8/20000),0)+ROUNDUP((C8/50000),0) -> 6
A5: Mainline Pavement Area: | C5: ='General Information'!D26 -> 45883 | D5: S.Y. | E5: Maintenance 2 Duration (Days) | F5: =ROUNDUP((C5/15000),0)+ROUNDUP((C8/20000),0)+ROUNDUP((C8/50000),0) -> 6
A6: Initial Construction Year: | C6: ='General Information'!D25 -> 2028 | E6: Maintenance 3 Duration (Days) | F6: =ROUNDUP((C5/15000),0)+ROUNDUP((C8/20000),0)+ROUNDUP((C8/50000),0)+ROUNDUP((C5*'Maintenance Policies'!D15/10000),0)+ROUNDUP((C5*'Maintenance Policies'!D14/5000),0) -> 8 | AP6: Mill and overlay: | AQ6: 2 | AR6: inches
A7: Asphalt Surface Treatment Type: | C7: Emulsified Asphalt Surface Treatment | D7: Select alternative treatment, if planned. | E7: Maintenance 4 Duration (Days) | F7: =ROUNDUP((C5/15000),0)+ROUNDUP((C8/20000),0)+ROUNDUP((C8/50000),0)+ROUNDUP((C5*'Maintenance Policies'!D18/10000),0)+ROUNDUP((C5*'Maintenance Policies'!D19/5000),0) -> 8 | AP7: Asphalt: | AQ7: 120 | AR7: lbs/SY-in
A8: Markings Area: | C8: ='General Information'!D28 -> 12000 | D8: S.F. | E8: Rehabilitation 1 Duration (Days) | F8: =ROUNDUP((C5/3800),0)+ROUNDUP((C8/50000),0) -> 14
E9: Maintenance 5 Duration (Days) | F9: =ROUNDUP((C5/15000),0)+ROUNDUP((C8/20000),0)+ROUNDUP((C8/50000),0) -> 6 | AP9: Tack Coat Application | AQ9: 0.1 | AR9: gal/S.Y.
E10: Maintenance 6 Duration (Days) | F10: =ROUNDUP((C5/15000),0)+ROUNDUP((C8/20000),0)+ROUNDUP((C8/50000),0)+ROUNDUP((C5*'Maintenance Policies'!D28/10000),0)+ROUNDUP((C5*'Maintenance Policies'!D29/5000),0) -> 8 | I10: Price column: 1 Regular, 2 Middle, 3 West, 4 East
B11: Price from: | C11: Regular | D11: =IF(OR($C$11="Regular",$C$11=""),"Regular is the statewide Unit Cost column on Pay_Items.","Prices from the "&$C$11&" column on Pay_Items: "&SUM($I$13:$I$22)&" of "&COUNT($I$13:$I$22)&" pay items used here have a "&$C$11&" cost, the rest fall back to Unit Cost.") -> Regular is the statewide Unit Cost column on Pay_Items. | I11: =IFERROR(MATCH($C$11,PriceSources,0),1) -> 1
A12: Item No. | B12: Pay Item | C12: Description | D12: Unit | E12: Qty | F12: Unit Cost | G12: Item Cost | J12: Item No. | K12: Pay Item | L12: Description | M12: Unit | N12: Qty | O12: Unit Cost | P12: Item Cost | R12: Item No. | S12: Pay Item | T12: Description | U12: Unit | V12: Qty | W12: Unit Cost | X12: Item Cost | Z12: Item No. | AA12: Pay Item | AB12: Description | AC12: Unit | AD12: Qty | AE12: Unit Cost | AF12: Item Cost | AH12: Item No. | AI12: Pay Item | AJ12: Description | AK12: Unit | AL12: Qty | AM12: Unit Cost | AN12: Item Cost | AP12: Item No. | AQ12: Pay Item | AR12: Description | AS12: Unit | AT12: Qty | AU12: Unit Cost | AV12: Item Cost | AX12: Item No. | AY12: Pay Item | AZ12: Description | BA12: Unit | BB12: Qty | BC12: Unit Cost | BD12: Item Cost | BF12: Item No. | BG12: Pay Item | BH12: Description | BI12: Unit | BJ12: Qty | BK12: Unit Cost | BL12: Item Cost
A13: 1 | B13: =IF(C13="","",VLOOKUP(C13,CHOOSE({1,2},Table2[Pay Item Description],Table2[Pay Item No.]),2,0)) | D13: =IF(C13="","N/A",VLOOKUP(C13,CHOOSE({1,2},Table2[Pay Item Description],Table2[Units]),2,0)) -> N/A | F13: =IF(C13="","N/A",IF(INDEX(UnitCostGrid,MATCH(C13,PayItemKeys,0),$I$11)="",INDEX(UnitCostGrid,MATCH(C13,PayItemKeys,0),1),INDEX(UnitCostGrid,MATCH(C13,PayItemKeys,0),$I$11))) -> N/A | G13: =IF(C13="",0,F13*E13) -> 0 | I13: =IF(C13="","",IF(INDEX(UnitCostGrid,MATCH(C13,PayItemKeys,0),$I$11)="",0,1)) | J13: 1 | K13: =IF(L13="",0,VLOOKUP(L13,CHOOSE({1,2},Table2[Pay Item Description],Table2[Pay Item No.]),2,0)) -> P-608-8.1 | L13: =C7 -> Emulsified Asphalt Surface Treatment | M13: =VLOOKUP(L13,CHOOSE({1,2},Table2[Pay Item Description],Table2[Units]),2,0) -> S.Y. | N13: ='Maintenance Policies'!D10*$C$5 -> 45883 | O13: =IF(L13="","N/A",IF(INDEX(UnitCostGrid,MATCH(L13,PayItemKeys,0),$I$11)="",INDEX(UnitCostGrid,MATCH(L13,PayItemKeys,0),1),INDEX(UnitCostGrid,MATCH(L13,PayItemKeys,0),$I$11))) -> 4 | P13: =O13*N13 -> 183532 | R13: 1 | S13: =IF(T13="",0,VLOOKUP(T13,CHOOSE({1,2},Table2[Pay Item Description],Table2[Pay Item No.]),2,0)) -> P-608-8.1 | T13: =C7 -> Emulsified Asphalt Surface Treatment | U13: =VLOOKUP(T13,CHOOSE({1,2},Table2[Pay Item Description],Table2[Units]),2,0) -> S.Y. | V13: ='Maintenance Policies'!D12*$C$5 -> 45883 | W13: =IF(T13="","N/A",IF(INDEX(UnitCostGrid,MATCH(T13,PayItemKeys,0),$I$11)="",INDEX(UnitCostGrid,MATCH(T13,PayItemKeys,0),1),INDEX(UnitCostGrid,MATCH(T13,PayItemKeys,0),$I$11))) -> 4 | X13: =W13*V13 -> 183532 | Z13: 1 | AA13: =IF(AB13="",0,VLOOKUP(AB13,CHOOSE({1,2},Table2[Pay Item Description],Table2[Pay Item No.]),2,0)) -> P-101-5.4a | AB13: =Pay_Items!D11 -> Spall Repair, Asphalt | AC13: =IF(AB13="","N/A",VLOOKUP(AB13,CHOOSE({1,2},Table2[Pay Item Description],Table2[Units]),2,0)) -> S.F. | AD13: ='Maintenance Policies'!D14*($C$5*9) -> 3097.1025 | AE13: =IF(AB13="","N/A",IF(INDEX(UnitCostGrid,MATCH(AB13,PayItemKeys,0),$I$11)="",INDEX(UnitCostGrid,MATCH(AB13,PayItemKeys,0),1),INDEX(UnitCostGrid,MATCH(AB13,PayItemKeys,0),$I$11))) -> 8.5 | AF13: =AE13*AD13 -> 26325.371 | AH13: 1 | AI13: =IF(AJ13="",0,VLOOKUP(AJ13,CHOOSE({1,2},Table2[Pay Item Description],Table2[Pay Item No.]),2,0)) -> P-101-5.4a | AJ13: =Pay_Items!D11 -> Spall Repair, Asphalt | AK13: =IF(AJ13="","N/A",VLOOKUP(AJ13,CHOOSE({1,2},Table2[Pay Item Description],Table2[Units]),2,0)) -> S.F. | AL13: ='Maintenance Policies'!D18*($C$5*9) -> 4129.47 | AM13: =IF(AJ13="","N/A",IF(INDEX(UnitCostGrid,MATCH(AJ13,PayItemKeys,0),$I$11)="",INDEX(UnitCostGrid,MATCH(AJ13,PayItemKeys,0),1),INDEX(UnitCostGrid,MATCH(AJ13,PayItemKeys,0),$I$11))) -> 8.5 | AN13: =AM13*AL13 -> 35100.495 | AP13: 1 | AQ13: =IF(AR13="",0,VLOOKUP(AR13,CHOOSE({1,2},Table2[Pay Item Description],Table2[Pay Item No.]),2,0)) -> P-101-5.6 | AR13: =Pay_Items!D16 -> Cold Milling | AS13: =IF(AR13="","N/A",VLOOKUP(AR13,CHOOSE({1,2},Table2[Pay Item Description],Table2[Units]),2,0)) -> S.Y. | AT13: ='Maintenance Policies'!D22*$C$5 -> 45883 | AU13: =IF(AR13="","N/A",IF(INDEX(UnitCostGrid,MATCH(AR13,PayItemKeys,0),$I$11)="",INDEX(UnitCostGrid,MATCH(AR13,PayItemKeys,0),1),INDEX(UnitCostGrid,MATCH(AR13,PayItemKeys,0),$I$11))) -> 5 | AV13: =AU13*AT13 -> 229415 | AX13: 1 | AY13: =IF(AZ13="",0,VLOOKUP(AZ13,CHOOSE({1,2},Table2[Pay Item Description],Table2[Pay Item No.]),2,0)) -> P-608-8.1 | AZ13: =C7 -> Emulsified Asphalt Surface Treatment | BA13: =IF(AZ13="","N/A",VLOOKUP(AZ13,CHOOSE({1,2},Table2[Pay Item Description],Table2[Units]),2,0)) -> S.Y. | BB13: ='Maintenance Policies'!D26*$C$5 -> 45883 | BC13: =IF(AZ13="","N/A",IF(INDEX(UnitCostGrid,MATCH(AZ13,PayItemKeys,0),$I$11)="",INDEX(UnitCostGrid,MATCH(AZ13,PayItemKeys,0),1),INDEX(UnitCostGrid,MATCH(AZ13,PayItemKeys,0),$I$11))) -> 4 | BD13: =BC13*BB13 -> 183532 | BF13: 1 | BG13: =IF(BH13="",0,VLOOKUP(BH13,CHOOSE({1,2},Table2[Pay Item Description],Table2[Pay Item No.]),2,0)) -> P-101-5.4a | BH13: =Pay_Items!D11 -> Spall Repair, Asphalt | BI13: =IF(BH13="","N/A",VLOOKUP(BH13,CHOOSE({1,2},Table2[Pay Item Description],Table2[Units]),2,0)) -> S.F. | BJ13: ='Maintenance Policies'!D28*($C$5*9) -> 5161.8375 | BK13: =IF(BH13="","N/A",IF(INDEX(UnitCostGrid,MATCH(BH13,PayItemKeys,0),$I$11)="",INDEX(UnitCostGrid,MATCH(BH13,PayItemKeys,0),1),INDEX(UnitCostGrid,MATCH(BH13,PayItemKeys,0),$I$11))) -> 8.5 | BL13: =BK13*BJ13 -> 43875.619
A14: 2 | B14: =IF(C14="","",VLOOKUP(C14,CHOOSE({1,2},Table2[Pay Item Description],Table2[Pay Item No.]),2,0)) | D14: =IF(C14="","N/A",VLOOKUP(C14,CHOOSE({1,2},Table2[Pay Item Description],Table2[Units]),2,0)) -> N/A | F14: =IF(C14="","N/A",IF(INDEX(UnitCostGrid,MATCH(C14,PayItemKeys,0),$I$11)="",INDEX(UnitCostGrid,MATCH(C14,PayItemKeys,0),1),INDEX(UnitCostGrid,MATCH(C14,PayItemKeys,0),$I$11))) -> N/A | G14: =IF(C14="",0,F14*E14) -> 0 | I14: =IF(C14="","",IF(INDEX(UnitCostGrid,MATCH(C14,PayItemKeys,0),$I$11)="",0,1)) | J14: 2 | K14: =IF(L14="",0,VLOOKUP(L14,CHOOSE({1,2},Table2[Pay Item Description],Table2[Pay Item No.]),2,0)) -> P-101-5.3 | L14: =Pay_Items!D10 -> Markings Removal | M14: =IF(L14="","N/A",VLOOKUP(L14,CHOOSE({1,2},Table2[Pay Item Description],Table2[Units]),2,0)) -> S.F. | N14: ='Maintenance Policies'!D10*$C$8 -> 12000 | O14: =IF(L14="","N/A",IF(INDEX(UnitCostGrid,MATCH(L14,PayItemKeys,0),$I$11)="",INDEX(UnitCostGrid,MATCH(L14,PayItemKeys,0),1),INDEX(UnitCostGrid,MATCH(L14,PayItemKeys,0),$I$11))) -> 0.77777778 | P14: =O14*N14 -> 9333.3333 | R14: 2 | S14: =IF(T14="",0,VLOOKUP(T14,CHOOSE({1,2},Table2[Pay Item Description],Table2[Pay Item No.]),2,0)) -> P-101-5.3 | T14: =Pay_Items!D10 -> Markings Removal | U14: =IF(T14="","N/A",VLOOKUP(T14,CHOOSE({1,2},Table2[Pay Item Description],Table2[Units]),2,0)) -> S.F. | V14: ='Maintenance Policies'!D12*$C$8 -> 12000 | W14: =IF(T14="","N/A",IF(INDEX(UnitCostGrid,MATCH(T14,PayItemKeys,0),$I$11)="",INDEX(UnitCostGrid,MATCH(T14,PayItemKeys,0),1),INDEX(UnitCostGrid,MATCH(T14,PayItemKeys,0),$I$11))) -> 0.77777778 | X14: =W14*V14 -> 9333.3333 | Z14: 2 | AA14: =IF(AB14="",0,VLOOKUP(AB14,CHOOSE({1,2},Table2[Pay Item Description],Table2[Pay Item No.]),2,0)) -> P-101-5.2a | AB14: =Pay_Items!D6 -> Crack Repair (Type I), Asphalt | AC14: =IF(AB14="","N/A",VLOOKUP(AB14,CHOOSE({1,2},Table2[Pay Item Description],Table2[Units]),2,0)) -> L.F. | AD14: ='Maintenance Policies'!D15*($C$5*9) -> 13420.778 | AE14: =IF(AB14="","N/A",IF(INDEX(UnitCostGrid,MATCH(AB14,PayItemKeys,0),$I$11)="",INDEX(UnitCostGrid,MATCH(AB14,PayItemKeys,0),1),INDEX(UnitCostGrid,MATCH(AB14,PayItemKeys,0),$I$11))) -> 4 | AF14: =AE14*AD14 -> 53683.11 | AH14: 2 | AI14: =IF(AJ14="",0,VLOOKUP(AJ14,CHOOSE({1,2},Table2[Pay Item Description],Table2[Pay Item No.]),2,0)) -> P-101-5.2a | AJ14: =Pay_Items!D6 -> Crack Repair (Type I), Asphalt | AK14: =IF(AJ14="","N/A",VLOOKUP(AJ14,CHOOSE({1,2},Table2[Pay Item Description],Table2[Units]),2,0)) -> L.F. | AL14: ='Maintenance Policies'!D19*($C$5*9) -> 14453.145 | AM14: =IF(AJ14="","N/A",IF(INDEX(UnitCostGrid,MATCH(AJ14,PayItemKeys,0),$I$11)="",INDEX(UnitCostGrid,MATCH(AJ14,PayItemKeys,0),1),INDEX(UnitCostGrid,MATCH(AJ14,PayItemKeys,0),$I$11))) -> 4 | AN14: =AM14*AL14 -> 57812.58 | AP14: 2 | AQ14: =IF(AR14="",0,VLOOKUP(AR14,CHOOSE({1,2},Table2[Pay Item Description],Table2[Pay Item No.]),2,0)) -> P-603-5.1 | AR14: =Pay_Items!D54 -> Emulsified Asphalt Tack Coat | AS14: =IF(AR14="","N/A",VLOOKUP(AR14,CHOOSE({1,2},Table2[Pay Item Description],Table2[Units]),2,0)) -> GAL | AT14: ='Maintenance Policies'!D22*$C$5*AQ9 -> 4588.3 | AU14: =IF(AR14="","N/A",IF(INDEX(UnitCostGrid,MATCH(AR14,PayItemKeys,0),$I$11)="",INDEX(UnitCostGrid,MATCH(AR14,PayItemKeys,0),1),INDEX(UnitCostGrid,MATCH(AR14,PayItemKeys,0),$I$11))) -> 4.5 | AV14: =AU14*AT14 -> 20647.35 | AX14: 2 | AY14: =IF(AZ14="",0,VLOOKUP(AZ14,CHOOSE({1,2},Table2[Pay Item Description],Table2[Pay Item No.]),2,0)) -> P-101-5.3 | AZ14: =Pay_Items!D10 -> Markings Removal | BA14: =IF(AZ14="","N/A",VLOOKUP(AZ14,CHOOSE({1,2},Table2[Pay Item Description],Table2[Units]),2,0)) -> S.F. | BB14: ='Maintenance Policies'!D26*$C$8 -> 12000 | BC14: =IF(AZ14="","N/A",IF(INDEX(UnitCostGrid,MATCH(AZ14,PayItemKeys,0),$I$11)="",INDEX(UnitCostGrid,MATCH(AZ14,PayItemKeys,0),1),INDEX(UnitCostGrid,MATCH(AZ14,PayItemKeys,0),$I$11))) -> 0.77777778 | BD14: =BC14*BB14 -> 9333.3333 | BF14: 2 | BG14: =IF(BH14="",0,VLOOKUP(BH14,CHOOSE({1,2},Table2[Pay Item Description],Table2[Pay Item No.]),2,0)) -> P-101-5.2a | BH14: =Pay_Items!D6 -> Crack Repair (Type I), Asphalt | BI14: =IF(BH14="","N/A",VLOOKUP(BH14,CHOOSE({1,2},Table2[Pay Item Description],Table2[Units]),2,0)) -> L.F. | BJ14: ='Maintenance Policies'!D29*($C$5*9) -> 16517.88 | BK14: =IF(BH14="","N/A",IF(INDEX(UnitCostGrid,MATCH(BH14,PayItemKeys,0),$I$11)="",INDEX(UnitCostGrid,MATCH(BH14,PayItemKeys,0),1),INDEX(UnitCostGrid,MATCH(BH14,PayItemKeys,0),$I$11))) -> 4 | BL14: =BK14*BJ14 -> 66071.52
A15: 3 | B15: =IF(C15="","",VLOOKUP(C15,CHOOSE({1,2},Table2[Pay Item Description],Table2[Pay Item No.]),2,0)) | D15: =IF(C15="","N/A",VLOOKUP(C15,CHOOSE({1,2},Table2[Pay Item Description],Table2[Units]),2,0)) -> N/A | F15: =IF(C15="","N/A",IF(INDEX(UnitCostGrid,MATCH(C15,PayItemKeys,0),$I$11)="",INDEX(UnitCostGrid,MATCH(C15,PayItemKeys,0),1),INDEX(UnitCostGrid,MATCH(C15,PayItemKeys,0),$I$11))) -> N/A | G15: =IF(C15="",0,F15*E15) -> 0 | I15: =IF(C15="","",IF(INDEX(UnitCostGrid,MATCH(C15,PayItemKeys,0),$I$11)="",0,1)) | J15: 3 | K15: =IF(L15="",0,VLOOKUP(L15,CHOOSE({1,2},Table2[Pay Item Description],Table2[Pay Item No.]),2,0)) -> P-620-5.1a | L15: =Pay_Items!D56 -> Markings (prep, markings, reflective media) | M15: =IF(L15="","N/A",VLOOKUP(L15,CHOOSE({1,2},Table2[Pay Item Description],Table2[Units]),2,0)) -> S.F. | N15: ='Maintenance Policies'!D11*$C$8 -> 12000 | O15: =IF(L15="","N/A",IF(INDEX(UnitCostGrid,MATCH(L15,PayItemKeys,0),$I$11)="",INDEX(UnitCostGrid,MATCH(L15,PayItemKeys,0),1),INDEX(UnitCostGrid,MATCH(L15,PayItemKeys,0),$I$11))) -> 0.66666667 | P15: =O15*N15 -> 8000 | R15: 3 | S15: =IF(T15="",0,VLOOKUP(T15,CHOOSE({1,2},Table2[Pay Item Description],Table2[Pay Item No.]),2,0)) -> P-620-5.1a | T15: =Pay_Items!D56 -> Markings (prep, markings, reflective media) | U15: =Pay_Items!E56 -> S.F. | V15: ='Maintenance Policies'!D13*$C$8 -> 12000 | W15: =IF(T15="","N/A",IF(INDEX(UnitCostGrid,MATCH(T15,PayItemKeys,0),$I$11)="",INDEX(UnitCostGrid,MATCH(T15,PayItemKeys,0),1),INDEX(UnitCostGrid,MATCH(T15,PayItemKeys,0),$I$11))) -> 0.66666667 | X15: =W15*V15 -> 8000 | Z15: 3 | AA15: =IF(AB15="",0,VLOOKUP(AB15,CHOOSE({1,2},Table2[Pay Item Description],Table2[Pay Item No.]),2,0)) -> P-608-8.1 | AB15: =C7 -> Emulsified Asphalt Surface Treatment | AC15: =IF(AB15="","N/A",VLOOKUP(AB15,CHOOSE({1,2},Table2[Pay Item Description],Table2[Units]),2,0)) -> S.Y. | AD15: ='Maintenance Policies'!D16*$C$5 -> 45883 | AE15: =IF(AB15="","N/A",IF(INDEX(UnitCostGrid,MATCH(AB15,PayItemKeys,0),$I$11)="",INDEX(UnitCostGrid,MATCH(AB15,PayItemKeys,0),1),INDEX(UnitCostGrid,MATCH(AB15,PayItemKeys,0),$I$11))) -> 4 | AF15: =AE15*AD15 -> 183532 | AH15: 3 | AI15: =IF(AJ15="",0,VLOOKUP(AJ15,CHOOSE({1,2},Table2[Pay Item Description],Table2[Pay Item No.]),2,0)) -> P-608-8.1 | AJ15: =C7 -> Emulsified Asphalt Surface Treatment | AK15: =IF(AJ15="","N/A",VLOOKUP(AJ15,CHOOSE({1,2},Table2[Pay Item Description],Table2[Units]),2,0)) -> S.Y. | AL15: ='Maintenance Policies'!D20*$C$5 -> 45883 | AM15: =IF(AJ15="","N/A",IF(INDEX(UnitCostGrid,MATCH(AJ15,PayItemKeys,0),$I$11)="",INDEX(UnitCostGrid,MATCH(AJ15,PayItemKeys,0),1),INDEX(UnitCostGrid,MATCH(AJ15,PayItemKeys,0),$I$11))) -> 4 | AN15: =AM15*AL15 -> 183532 | AP15: 3 | AQ15: =IF(AR15="",0,VLOOKUP(AR15,CHOOSE({1,2},Table2[Pay Item Description],Table2[Pay Item No.]),2,0)) -> P-401-8.1a | AR15: =Pay_Items!D37 -> Asphalt Surface Course | AS15: =IF(AR15="","N/A",VLOOKUP(AR15,CHOOSE({1,2},Table2[Pay Item Description],Table2[Units]),2,0)) -> TON | AT15: ='Maintenance Policies'!D22*$C$5*AQ6*AQ7/2000 -> 5505.96 | AU15: =IF(AR15="","N/A",IF(INDEX(UnitCostGrid,MATCH(AR15,PayItemKeys,0),$I$11)="",INDEX(UnitCostGrid,MATCH(AR15,PayItemKeys,0),1),INDEX(UnitCostGrid,MATCH(AR15,PayItemKeys,0),$I$11))) -> 130 | AV15: =AU15*AT15 -> 715774.8 | AX15: 3 | AY15: =IF(AZ15="",0,VLOOKUP(AZ15,CHOOSE({1,2},Table2[Pay Item Description],Table2[Pay Item No.]),2,0)) -> P-620-5.1a | AZ15: =Pay_Items!D56 -> Markings (prep, markings, reflective media) | BA15: =IF(AZ15="","N/A",VLOOKUP(AZ15,CHOOSE({1,2},Table2[Pay Item Description],Table2[Units]),2,0)) -> S.F. | BB15: ='Maintenance Policies'!D27*$C$8 -> 12000 | BC15: =IF(AZ15="","N/A",IF(INDEX(UnitCostGrid,MATCH(AZ15,PayItemKeys,0),$I$11)="",INDEX(UnitCostGrid,MATCH(AZ15,PayItemKeys,0),1),INDEX(UnitCostGrid,MATCH(AZ15,PayItemKeys,0),$I$11))) -> 0.66666667 | BD15: =BC15*BB15 -> 8000 | BF15: 3 | BG15: =IF(BH15="",0,VLOOKUP(BH15,CHOOSE({1,2},Table2[Pay Item Description],Table2[Pay Item No.]),2,0)) -> P-608-8.1 | BH15: =C7 -> Emulsified Asphalt Surface Treatment | BI15: =IF(BH15="","N/A",VLOOKUP(BH15,CHOOSE({1,2},Table2[Pay Item Description],Table2[Units]),2,0)) -> S.Y. | BJ15: ='Maintenance Policies'!D30*$C$5 -> 45883 | BK15: =IF(BH15="","N/A",IF(INDEX(UnitCostGrid,MATCH(BH15,PayItemKeys,0),$I$11)="",INDEX(UnitCostGrid,MATCH(BH15,PayItemKeys,0),1),INDEX(UnitCostGrid,MATCH(BH15,PayItemKeys,0),$I$11))) -> 4 | BL15: =BK15*BJ15 -> 183532
